Workbook

Sheet Data Kyu
A1: SIMPERKEMI EVENT | C1: Gashuku dan Ujian Kenaikan Tingkat Kota Xxxxxxx Ke-1 Tahun 2026 | N1: Get Data :
A2: Peserta Ujian Approved by PB. PERKEMI | C2: Jl. Xxxxxxx, Kel. Xxxxxxx, Kec, Xxxxxxx, 09-01-2026 sd 10-01-2026 | N2: 46048.302
A3: No | B3: Nama Kenshi | C3: NIK | D3: Gender | E3: Usia UKT (Thn) | F3: Tgl Lahir | I3: Ujian Ke | J3: Dojo | K3: Cabang | L3: Provinsi | M3: Status | N3: Keterangan | P3: Petunjuk :
B5: Ujian Menuju 8 KYU | P5: Ganti contoh data peserta disamping ini dengan data peserta ujian hasil download dari SIMPERKEMI pada menu Permohonan Mandat Penguji (kolom A sd M), dan isi kolom Keterangan (N) dengan LULUS / TIDAK LULUS / TIDAK HADIR sesuai hasil di laporan F-28 yang telah dibuat.
A6: 1 | B6: Kenshi 1 | C6: XX.X.XX.XX.XX.001 | D6: Male | E6: 7.21 | F6: 2018 | G6: 10 | H6: 01 | I6: 8 KYU | J6: Xxxxx Xxxxxx | K6: Xxxxxx. Kab. | L6: Xxxxxx | M6: approved | N6: LULUS
A7: 2 | B7: Kenshi 2 | C7: XX.X.XX.XX.XX.002 | D7: Male | E7: 7.21 | F7: 2018 | G7: 11 | H7: 02 | I7: 8 KYU | J7: Xxxxx Xxxxxx | K7: Xxxxxx. Kab. | L7: Xxxxxx | M7: approved | N7: LULUS
A8: 3 | B8: Kenshi 3 | C8: XX.X.XX.XX.XX.003 | D8: Male | E8: 7.21 | F8: 2018 | G8: 12 | H8: 03 | I8: 8 KYU | J8: Xxxxx Xxxxxx | K8: Xxxxxx. Kab. | L8: Xxxxxx | M8: approved | N8: LULUS
A9: 4 | B9: Kenshi 4 | C9: XX.X.XX.XX.XX.004 | D9: Male | E9: 7.21 | F9: 2018 | G9: 13 | H9: 04 | I9: 8 KYU | J9: Xxxxx Xxxxxx | K9: Xxxxxx. Kab. | L9: Xxxxxx | M9: approved | N9: TIDAK HADIR
A10: 5 | B10: Kenshi 5 | C10: XX.X.XX.XX.XX.005 | D10: Female | E10: 7.21 | F10: 2018 | G10: 14 | H10: 05 | I10: 8 KYU | J10: Xxxxx Xxxxxx | K10: Xxxxxx. Kab. | L10: Xxxxxx | M10: approved | N10: TIDAK HADIR
B11: Ujian Menuju 7 KYU
A12: 6 | B12: Kenshi 6 | C12: XX.X.XX.XX.XX.006 | D12: Male | E12: 9.62 | F12: 2016 | G12: 06 | H12: 01 | I12: 7 KYU | J12: Xxxxx Xxxxxx | K12: Xxxxxx. Kab. | L12: Xxxxxx | M12: approved | N12: LULUS
A13: 7 | B13: Kenshi 7 | C13: XX.X.XX.XX.XX.007 | D13: Male | E13: 9.62 | F13: 2016 | G13: 07 | H13: 02 | I13: 7 KYU | J13: Xxxxx Xxxxxx | K13: Xxxxxx. Kab. | L13: Xxxxxx | M13: approved | N13: LULUS
A14: 8 | B14: Kenshi 8 | C14: XX.X.XX.XX.XX.008 | D14: Female | E14: 9.62 | F14: 2016 | G14: 08 | H14: 03 | I14: 7 KYU | J14: Xxxxx Xxxxxx | K14: Xxxxxx. Kab. | L14: Xxxxxx | M14: approved | N14: LULUS
A15: 9 | B15: Kenshi 9 | C15: XX.X.XX.XX.XX.009 | D15: Female | E15: 9.62 | F15: 2016 | G15: 09 | H15: 04 | I15: 7 KYU | J15: Xxxxx Xxxxxx | K15: Xxxxxx. Kab. | L15: Xxxxxx | M15: approved | N15: LULUS
A16: 10 | B16: Kenshi 10 | C16: XX.X.XX.XX.XX.010 | D16: Female | E16: 9.62 | F16: 2016 | G16: 10 | H16: 05 | I16: 7 KYU | J16: Xxxxx Xxxxxx | K16: Xxxxxx. Kab. | L16: Xxxxxx | M16: approved | N16: LULUS
B17: Ujian Menuju 6 KYU | P17: atau Copas dari sini :
A18: 11 | B18: Kenshi 11 | C18: XX.X.XX.XX.XX.011 | D18: Male | E18: 7.21 | F18: 2018 | G18: 10 | H18: 01 | I18: 6 KYU | J18: Xxxxx Xxxxxx | K18: Xxxxxx. Kab. | L18: Xxxxxx | M18: approved | N18: LULUS
A19: 12 | B19: Kenshi 12 | C19: XX.X.XX.XX.XX.012 | D19: Male | E19: 7.21 | F19: 2018 | G19: 11 | H19: 02 | I19: 6 KYU | J19: Xxxxx Xxxxxx | K19: Xxxxxx. Kab. | L19: Xxxxxx | M19: approved | N19: LULUS | P19: LULUS
A20: 13 | B20: Kenshi 13 | C20: XX.X.XX.XX.XX.013 | D20: Male | E20: 7.21 | F20: 2018 | G20: 12 | H20: 03 | I20: 6 KYU | J20: Xxxxx Xxxxxx | K20: Xxxxxx. Kab. | L20: Xxxxxx | M20: approved | N20: LULUS | P20: TIDAK LULUS
A21: 14 | B21: Kenshi 14 | C21: XX.X.XX.XX.XX.014 | D21: Male | E21: 7.21 | F21: 2018 | G21: 13 | H21: 04 | I21: 6 KYU | J21: Xxxxx Xxxxxx | K21: Xxxxxx. Kab. | L21: Xxxxxx | M21: approved | N21: LULUS | P21: TIDAK HADIR
A22: 15 | B22: Kenshi 15 | C22: XX.X.XX.XX.XX.015 | D22: Female | E22: 7.21 | F22: 2018 | G22: 14 | H22: 05 | I22: 6 KYU | J22: Xxxxx Xxxxxx | K22: Xxxxxx. Kab. | L22: Xxxxxx | M22: approved | N22: TIDAK HADIR
B23: Ujian Menuju 5 KYU
A24: 16 | B24: Kenshi 16 | C24: XX.X.XX.XX.XX.016 | D24: Male | E24: 9.62 | F24: 2016 | G24: 06 | H24: 01 | I24: 5 KYU | J24: Xxxxx Xxxxxx | K24: Xxxxxx. Kab. | L24: Xxxxxx | M24: approved | N24: LULUS | P24: Data peserta setelah terisi keterangan Lulus sesuai laporan hasil ujian (F-28), WAJIB diurutkan kembali berdasarkan urutan kolom Keterangan (urutkan dari dari LULUS sd TIDAK LULUS/TIDAK HADIR), dengan menggunakan fungsi Data --> Sort (sort by Column N). Agar yang tidak Lulus berada di urutan terakhir data setiap tingkatannya.
A25: 17 | B25: Kenshi 17 | C25: XX.X.XX.XX.XX.017 | D25: Male | E25: 9.62 | F25: 2016 | G25: 07 | H25: 02 | I25: 5 KYU | J25: Xxxxx Xxxxxx | K25: Xxxxxx. Kab. | L25: Xxxxxx | M25: approved | N25: LULUS
A26: 18 | B26: Kenshi 18 | C26: XX.X.XX.XX.XX.018 | D26: Female | E26: 9.62 | F26: 2016 | G26: 08 | H26: 03 | I26: 5 KYU | J26: Xxxxx Xxxxxx | K26: Xxxxxx. Kab. | L26: Xxxxxx | M26: approved | N26: LULUS
A27: 19 | B27: Kenshi 19 | C27: XX.X.XX.XX.XX.019 | D27: Female | E27: 9.62 | F27: 2016 | G27: 09 | H27: 04 | I27: 5 KYU | J27: Xxxxx Xxxxxx | K27: Xxxxxx. Kab. | L27: Xxxxxx | M27: approved | N27: LULUS
A28: 20 | B28: Kenshi 20 | C28: XX.X.XX.XX.XX.020 | D28: Female | E28: 9.62 | F28: 2016 | G28: 10 | H28: 05 | I28: 5 KYU | J28: Xxxxx Xxxxxx | K28: Xxxxxx. Kab. | L28: Xxxxxx | M28: approved | N28: LULUS
B29: Ujian Menuju 4 KYU
A30: 21 | B30: Kenshi 21 | C30: XX.X.XX.XX.XX.021 | D30: Male | E30: 19.23 | F30: 2018 | G30: 10 | H30: 01 | I30: 4 KYU | J30: Xxxxx Xxxxxx | K30: Xxxxxx. Kab. | L30: Xxxxxx | M30: approved | N30: LULUS
A31: 22 | B31: Kenshi 22 | C31: XX.X.XX.XX.XX.022 | D31: Male | E31: 8.57 | F31: 2018 | G31: 11 | H31: 02 | I31: 4 KYU | J31: Xxxxx Xxxxxx | K31: Xxxxxx. Kab. | L31: Xxxxxx | M31: approved | N31: LULUS
A32: 23 | B32: Kenshi 23 | C32: XX.X.XX.XX.XX.023 | D32: Male | E32: 19.52 | F32: 2018 | G32: 12 | H32: 03 | I32: 4 KYU | J32: Xxxxx Xxxxxx | K32: Xxxxxx. Kab. | L32: Xxxxxx | M32: approved | N32: LULUS
A33: 24 | B33: Kenshi 24 | C33: XX.X.XX.XX.XX.024 | D33: Male | E33: 20.53 | F33: 2018 | G33: 13 | H33: 04 | I33: 4 KYU | J33: Xxxxx Xxxxxx | K33: Xxxxxx. Kab. | L33: Xxxxxx | M33: approved | N33: TIDAK HADIR
A34: 25 | B34: Kenshi 25 | C34: XX.X.XX.XX.XX.025 | D34: Female | E34: 19.59 | F34: 2018 | G34: 14 | H34: 05 | I34: 4 KYU | J34: Xxxxx Xxxxxx | K34: Xxxxxx. Kab. | L34: Xxxxxx | M34: approved | N34: TIDAK HADIR
B35: Ujian Menuju 3 KYU
A36: 26 | B36: Kenshi 26 | C36: XX.X.XX.XX.XX.026 | D36: Male | E36: 13.46 | F36: 2012 | G36: 07 | H36: 29 | I36: 3 KYU | J36: Xxxxx Xxxxxx | K36: Xxxxxx. Kab. | L36: Xxxxxx | M36: approved | N36: LULUS
A37: 27 | B37: Kenshi 27 | C37: XX.X.XX.XX.XX.027 | D37: Male | E37: 36.22 | F37: 1989 | G37: 10 | H37: 30 | I37: 3 KYU | J37: Xxxxx Xxxxxx | K37: Xxxxxx. Kab. | L37: Xxxxxx | M37: approved | N37: LULUS
A38: 28 | B38: Kenshi 28 | C38: XX.X.XX.XX.XX.028 | D38: Male | E38: 36.84 | F38: 1989 | G38: 03 | H38: 18 | I38: 3 KYU | J38: Xxxxx Xxxxxx | K38: Xxxxxx. Kab. | L38: Xxxxxx | M38: approved | N38: LULUS
A39: 29 | B39: Kenshi 29 | C39: XX.X.XX.XX.XX.029 | D39: Female | E39: 15.31 | F39: 2010 | G39: 09 | H39: 24 | I39: 3 KYU | J39: Xxxxx Xxxxxx | K39: Xxxxxx. Kab. | L39: Xxxxxx | M39: approved | N39: LULUS
A40: 30 | B40: Kenshi 30 | C40: XX.X.XX.XX.XX.030 | D40: Female | E40: 19.85 | F40: 2006 | G40: 03 | H40: 11 | I40: 3 KYU | J40: Xxxxx Xxxxxx | K40: Xxxxxx. Kab. | L40: Xxxxxx | M40: approved | N40: LULUS
B41: Ujian Menuju 2 KYU
...

Sheet KYU Report
B2: 昇 級 上 申 書 | K2: 支部名 Branch | L2: INDONESIA | X2: JANGAN HAPUS INFO KOLOM DIBAWAH INI !
B3: Kyu Examination Report | K3: Branch No | L3: 4 | M3: 1 | N3: 0 | O3: 0 | Q3: 0 | R3: 1
B4: SHORINJI KEMPO UNITY 代表理事 宗 昂馬 様 | X4: Note :
B5: To: Mr. Kouma So, Representative Director, Shorinji Kempo Unity | K5: Year | L5: 2026 | N5: / Month | Q5: 1 | S5: / Day | U5: 5 | X5: Tanggal yang diisi hanya pada baris ini, tanggal berikutnya otomatis akan terisi dengan tanggal yang sama.
B7: 昇級考試を実施した結果、下記の受験者が合格しましたことを上申致します。 | X7: Isi dengan tanggal pembuatan laporan atau sama dengan tanggal pelantikan ujian
B8: I, the undersigned, hereby report that the following applicants passed the Kyu examination.
B10: 考試日 Examination Date | G10: Year | H10: =$L$5 -> 2026 | I10: / Month | J10: =$Q$5 -> 1 | K10: / Day | L10: =$U$5 -> 5 | X10: Isi dengan tanggal pelantikan ujian
B12: ＊10 歳以上の拳士は原則として 6 級からの受験になりますが、個々の事情により 7、8 級を受験する場合には、この欄にチェックを入れてください。
B13: N.B. | E13: As a general rule, kenshi aged 10 or older should commence grading examinations from 6th Kyu.
E14: Please indicate in the first column (using a ✓) if he/ she took an examination for 7th or 8th Kyu for any given reason. | X14: Note :
E16: No | F16: 拳士コード Kenshi No. | L16: 級 | N16: 生年月日 | V16: 性別 | X16: Kolom C (tanda "V") / Lulus, otomatis akan terisi jika peserta dinyatakan Lulus.
F17: 合格者氏名（ローマ字）Name of Applicant/s who passed (in alphabetical order) | L17: Kyu | N17: Date of Birth | V17: Gender
E18: 1 | F18: =_xlfn.IFNA(VLOOKUP(E18,'Data Kyu'!$A$6:$I$471,3,0),"") -> XX.X.XX.XX.XX.001 | L18: =_xlfn.IFNA(VLOOKUP(E18,'Data Kyu'!$A$6:$I$471,9,0),"") -> 8 KYU | N18: =_xlfn.IFNA(VLOOKUP(E18,'Data Kyu'!$A$6:$I$471,6,0),"") -> 2018 | P18: / | Q18: =_xlfn.IFNA(VLOOKUP(E18,'Data Kyu'!$A$6:$I$471,7,0),"") -> 10 | S18: / | T18: =_xlfn.IFNA(VLOOKUP(E18,'Data Kyu'!$A$6:$I$471,8,0),"") -> 01 | V18: =_xlfn.IFNA(VLOOKUP(E18,'Data Kyu'!$A$6:$I$471,4,0),"") -> Male | X18: =_xlfn.IFNA(VLOOKUP(F18,'Data Kyu'!$C$6:$N$997,12,0),"No Data") -> LULUS
C19: =IF(X18="LULUS","V","") -> V
F20: =_xlfn.IFNA(VLOOKUP(E18,'Data Kyu'!$A$6:$I$471,2,0),"") -> Kenshi 1 | N20: Year | Q20: Month | T20: Day
E22: 2 | F22: =_xlfn.IFNA(VLOOKUP(E22,'Data Kyu'!$A$6:$I$471,3,0),"") -> XX.X.XX.XX.XX.002 | L22: =_xlfn.IFNA(VLOOKUP(E22,'Data Kyu'!$A$6:$I$471,9,0),"") -> 8 KYU | N22: =_xlfn.IFNA(VLOOKUP(E22,'Data Kyu'!$A$6:$I$471,6,0),"") -> 2018 | P22: / | Q22: =_xlfn.IFNA(VLOOKUP(E22,'Data Kyu'!$A$6:$I$471,7,0),"") -> 11 | S22: / | T22: =_xlfn.IFNA(VLOOKUP(E22,'Data Kyu'!$A$6:$I$471,8,0),"") -> 02 | V22: =_xlfn.IFNA(VLOOKUP(E22,'Data Kyu'!$A$6:$I$471,4,0),"") -> Male | X22: =_xlfn.IFNA(VLOOKUP(F22,'Data Kyu'!$C$6:$N$997,12,0),"No Data") -> LULUS
C23: =IF(X22="LULUS","V","") -> V
F24: =_xlfn.IFNA(VLOOKUP(E22,'Data Kyu'!$A$6:$I$471,2,0),"") -> Kenshi 2 | N24: Year | Q24: Month | T24: Day
E26: 3 | F26: =_xlfn.IFNA(VLOOKUP(E26,'Data Kyu'!$A$6:$I$471,3,0),"") -> XX.X.XX.XX.XX.003 | L26: =_xlfn.IFNA(VLOOKUP(E26,'Data Kyu'!$A$6:$I$471,9,0),"") -> 8 KYU | N26: =_xlfn.IFNA(VLOOKUP(E26,'Data Kyu'!$A$6:$I$471,6,0),"") -> 2018 | P26: / | Q26: =_xlfn.IFNA(VLOOKUP(E26,'Data Kyu'!$A$6:$I$471,7,0),"") -> 12 | S26: / | T26: =_xlfn.IFNA(VLOOKUP(E26,'Data Kyu'!$A$6:$I$471,8,0),"") -> 03 | V26: =_xlfn.IFNA(VLOOKUP(E26,'Data Kyu'!$A$6:$I$471,4,0),"") -> Male | X26: =_xlfn.IFNA(VLOOKUP(F26,'Data Kyu'!$C$6:$N$997,12,0),"No Data") -> LULUS
C27: =IF(X26="LULUS","V","") -> V
F28: =_xlfn.IFNA(VLOOKUP(E26,'Data Kyu'!$A$6:$I$471,2,0),"") -> Kenshi 3 | N28: Year | Q28: Month | T28: Day
E30: 4 | F30: =_xlfn.IFNA(VLOOKUP(E30,'Data Kyu'!$A$6:$I$471,3,0),"") -> XX.X.XX.XX.XX.004 | L30: =_xlfn.IFNA(VLOOKUP(E30,'Data Kyu'!$A$6:$I$471,9,0),"") -> 8 KYU | N30: =_xlfn.IFNA(VLOOKUP(E30,'Data Kyu'!$A$6:$I$471,6,0),"") -> 2018 | P30: / | Q30: =_xlfn.IFNA(VLOOKUP(E30,'Data Kyu'!$A$6:$I$471,7,0),"") -> 13 | S30: / | T30: =_xlfn.IFNA(VLOOKUP(E30,'Data Kyu'!$A$6:$I$471,8,0),"") -> 04 | V30: =_xlfn.IFNA(VLOOKUP(E30,'Data Kyu'!$A$6:$I$471,4,0),"") -> Male | X30: =_xlfn.IFNA(VLOOKUP(F30,'Data Kyu'!$C$6:$N$997,12,0),"No Data") -> TIDAK HADIR
C31: =IF(X30="LULUS","V","")
F32: =_xlfn.IFNA(VLOOKUP(E30,'Data Kyu'!$A$6:$I$471,2,0),"") -> Kenshi 4 | N32: Year | Q32: Month | T32: Day
E34: 5 | F34: =_xlfn.IFNA(VLOOKUP(E34,'Data Kyu'!$A$6:$I$471,3,0),"") -> XX.X.XX.XX.XX.005 | L34: =_xlfn.IFNA(VLOOKUP(E34,'Data Kyu'!$A$6:$I$471,9,0),"") -> 8 KYU | N34: =_xlfn.IFNA(VLOOKUP(E34,'Data Kyu'!$A$6:$I$471,6,0),"") -> 2018 | P34: / | Q34: =_xlfn.IFNA(VLOOKUP(E34,'Data Kyu'!$A$6:$I$471,7,0),"") -> 14 | S34: / | T34: =_xlfn.IFNA(VLOOKUP(E34,'Data Kyu'!$A$6:$I$471,8,0),"") -> 05 | V34: =_xlfn.IFNA(VLOOKUP(E34,'Data Kyu'!$A$6:$I$471,4,0),"") -> Female | X34: =_xlfn.IFNA(VLOOKUP(F34,'Data Kyu'!$C$6:$N$997,12,0),"No Data") -> TIDAK HADIR
C35: =IF(X34="LULUS","V","")
F36: =_xlfn.IFNA(VLOOKUP(E34,'Data Kyu'!$A$6:$I$471,2,0),"") -> Kenshi 5 | N36: Year | Q36: Month | T36: Day
E38: 6 | F38: =_xlfn.IFNA(VLOOKUP(E38,'Data Kyu'!$A$6:$I$471,3,0),"") -> XX.X.XX.XX.XX.006 | L38: =_xlfn.IFNA(VLOOKUP(E38,'Data Kyu'!$A$6:$I$471,9,0),"") -> 7 KYU | N38: =_xlfn.IFNA(VLOOKUP(E38,'Data Kyu'!$A$6:$I$471,6,0),"") -> 2016 | P38: / | Q38: =_xlfn.IFNA(VLOOKUP(E38,'Data Kyu'!$A$6:$I$471,7,0),"") -> 06 | S38: / | T38: =_xlfn.IFNA(VLOOKUP(E38,'Data Kyu'!$A$6:$I$471,8,0),"") -> 01 | V38: =_xlfn.IFNA(VLOOKUP(E38,'Data Kyu'!$A$6:$I$471,4,0),"") -> Male | X38: =_xlfn.IFNA(VLOOKUP(F38,'Data Kyu'!$C$6:$N$997,12,0),"No Data") -> LULUS
C39: =IF(X38="LULUS","V","") -> V
F40: =_xlfn.IFNA(VLOOKUP(E38,'Data Kyu'!$A$6:$I$471,2,0),"") -> Kenshi 6 | N40: Year | Q40: Month | T40: Day
E42: 7 | F42: =_xlfn.IFNA(VLOOKUP(E42,'Data Kyu'!$A$6:$I$471,3,0),"") -> XX.X.XX.XX.XX.007 | L42: =_xlfn.IFNA(VLOOKUP(E42,'Data Kyu'!$A$6:$I$471,9,0),"") -> 7 KYU | N42: =_xlfn.IFNA(VLOOKUP(E42,'Data Kyu'!$A$6:$I$471,6,0),"") -> 2016 | P42: / | Q42: =_xlfn.IFNA(VLOOKUP(E42,'Data Kyu'!$A$6:$I$471,7,0),"") -> 07 | S42: / | T42: =_xlfn.IFNA(VLOOKUP(E42,'Data Kyu'!$A$6:$I$471,8,0),"") -> 02 | V42: =_xlfn.IFNA(VLOOKUP(E42,'Data Kyu'!$A$6:$I$471,4,0),"") -> Male | X42: =_xlfn.IFNA(VLOOKUP(F42,'Data Kyu'!$C$6:$N$997,12,0),"No Data") -> LULUS
C43: =IF(X42="LULUS","V","") -> V
F44: =_xlfn.IFNA(VLOOKUP(E42,'Data Kyu'!$A$6:$I$471,2,0),"") -> Kenshi 7 | N44: Year | Q44: Month | T44: Day
E46: 8 | F46: =_xlfn.IFNA(VLOOKUP(E46,'Data Kyu'!$A$6:$I$471,3,0),"") -> XX.X.XX.XX.XX.008 | L46: =_xlfn.IFNA(VLOOKUP(E46,'Data Kyu'!$A$6:$I$471,9,0),"") -> 7 KYU | N46: =_xlfn.IFNA(VLOOKUP(E46,'Data Kyu'!$A$6:$I$471,6,0),"") -> 2016 | P46: / | Q46: =_xlfn.IFNA(VLOOKUP(E46,'Data Kyu'!$A$6:$I$471,7,0),"") -> 08 | S46: / | T46: =_xlfn.IFNA(VLOOKUP(E46,'Data Kyu'!$A$6:$I$471,8,0),"") -> 03 | V46: =_xlfn.IFNA(VLOOKUP(E46,'Data Kyu'!$A$6:$I$471,4,0),"") -> Female | X46: =_xlfn.IFNA(VLOOKUP(F46,'Data Kyu'!$C$6:$N$997,12,0),"No Data") -> LULUS
C47: =IF(X46="LULUS","V","") -> V
F48: =_xlfn.IFNA(VLOOKUP(E46,'Data Kyu'!$A$6:$I$471,2,0),"") -> Kenshi 8 | N48: Year | Q48: Month | T48: Day
E50: 9 | F50: =_xlfn.IFNA(VLOOKUP(E50,'Data Kyu'!$A$6:$I$471,3,0),"") -> XX.X.XX.XX.XX.009 | L50: =_xlfn.IFNA(VLOOKUP(E50,'Data Kyu'!$A$6:$I$471,9,0),"") -> 7 KYU | N50: =_xlfn.IFNA(VLOOKUP(E50,'Data Kyu'!$A$6:$I$471,6,0),"") -> 2016 | P50: / | Q50: =_xlfn.IFNA(VLOOKUP(E50,'Data Kyu'!$A$6:$I$471,7,0),"") -> 09 | S50: / | T50: =_xlfn.IFNA(VLOOKUP(E50,'Data Kyu'!$A$6:$I$471,8,0),"") -> 04 | V50: =_xlfn.IFNA(VLOOKUP(E50,'Data Kyu'!$A$6:$I$471,4,0),"") -> Female | X50: =_xlfn.IFNA(VLOOKUP(F50,'Data Kyu'!$C$6:$N$997,12,0),"No Data") -> LULUS
C51: =IF(X50="LULUS","V","") -> V
F52: =_xlfn.IFNA(VLOOKUP(E50,'Data Kyu'!$A$6:$I$471,2,0),"") -> Kenshi 9 | N52: Year | Q52: Month | T52: Day
E54: 10 | F54: =_xlfn.IFNA(VLOOKUP(E54,'Data Kyu'!$A$6:$I$471,3,0),"") -> XX.X.XX.XX.XX.010 | L54: =_xlfn.IFNA(VLOOKUP(E54,'Data Kyu'!$A$6:$I$471,9,0),"") -> 7 KYU | N54: =_xlfn.IFNA(VLOOKUP(E54,'Data Kyu'!$A$6:$I$471,6,0),"") -> 2016 | P54: / | Q54: =_xlfn.IFNA(VLOOKUP(E54,'Data Kyu'!$A$6:$I$471,7,0),"") -> 10 | S54: / | T54: =_xlfn.IFNA(VLOOKUP(E54,'Data Kyu'!$A$6:$I$471,8,0),"") -> 05 | V54: =_xlfn.IFNA(VLOOKUP(E54,'Data Kyu'!$A$6:$I$471,4,0),"") -> Female | X54: =_xlfn.IFNA(VLOOKUP(F54,'Data Kyu'!$C$6:$N$997,12,0),"No Data") -> LULUS
...

Sheet Data Dan
A1: SIMPERKEMI EVENT | C1: Gashuku dan Ujian Kenaikan Tingkat Provinsi Xxxxxxx Ke-1 Tahun 2026 | N1: Get Data :
A2: Peserta Ujian Approved by PB. PERKEMI | C2: Jl. Xxxxxxx, Kel. Xxxxxxx, Kec, Xxxxxxx, 01-01-2026 sd 02-01-2026 | N2: 46038.302
A3: No | B3: Nama Kenshi | C3: NIK | D3: Gender | E3: Usia UKT (Thn) | F3: Tgl Lahir | I3: Ujian Ke | J3: Dojo | K3: Cabang | L3: Provinsi | M3: Status | N3: Keterangan | P3: Petunjuk :
B5: Ujian Menuju 1 DAN | P5: Ganti contoh data peserta menuju 1 DAN disamping ini dengan data peserta ujian hasil download dari SIMPERKEMI pada menu Permohonan Mandat Penguji (kolom A sd M), dan isi kolom Keterangan (N) dengan LULUS / TIDAK LULUS / TIDAK HADIR sesuai hasil di laporan F-28 yang telah dibuat.
A6: 1 | B6: Kenshi 1 | C6: XX.X.XX.XX.XX.001 | D6: Male | E6: 31.7 | F6: 1994 | G6: 06 | H6: 02 | I6: 1 DAN | J6: Xxxxx Xxxxxx | K6: Xxxxxx. Kab. | L6: Xxxxxx | M6: approved | N6: LULUS
A7: 2 | B7: Kenshi 2 | C7: XX.X.XX.XX.XX.002 | D7: Male | E7: 31.7 | F7: 1994 | G7: 06 | H7: 02 | I7: 1 DAN | J7: Xxxxx Xxxxxx | K7: Xxxxxx. Kab. | L7: Xxxxxx | M7: approved | N7: LULUS
A8: 3 | B8: Kenshi 3 | C8: XX.X.XX.XX.XX.003 | D8: Male | E8: 21.6 | F8: 2004 | G8: 07 | H8: 04 | I8: 1 DAN | J8: Xxxxx Xxxxxx | K8: Xxxxxx. Kab. | L8: Xxxxxx | M8: approved | N8: LULUS
A9: 4 | B9: Kenshi 4 | C9: XX.X.XX.XX.XX.004 | D9: Male | E9: 26.76 | F9: 1999 | G9: 05 | H9: 09 | I9: 1 DAN | J9: Xxxxx Xxxxxx | K9: Xxxxxx. Kab. | L9: Xxxxxx | M9: approved | N9: LULUS
A10: 5 | B10: Kenshi 5 | C10: XX.X.XX.XX.XX.005 | D10: Male | E10: 21.6 | F10: 2004 | G10: 07 | H10: 04 | I10: 1 DAN | J10: Xxxxx Xxxxxx | K10: Xxxxxx. Kab. | L10: Xxxxxx | M10: approved | N10: LULUS
A11: 6 | B11: Kenshi 6 | C11: XX.X.XX.XX.XX.006 | D11: Male | E11: 49.75 | F11: 1976 | G11: 05 | H11: 19 | I11: 1 DAN | J11: Xxxxx Xxxxxx | K11: Xxxxxx. Kab. | L11: Xxxxxx | M11: approved | N11: LULUS
A12: 7 | B12: Kenshi 7 | C12: XX.X.XX.XX.XX.007 | D12: Male | E12: 52.7 | F12: 1973 | G12: 06 | H12: 07 | I12: 1 DAN | J12: Xxxxx Xxxxxx | K12: Xxxxxx. Kota | L12: Xxxxxx | M12: approved | N12: LULUS
A13: 8 | B13: Kenshi 8 | C13: XX.X.XX.XX.XX.008 | D13: Male | E13: 31.7 | F13: 1994 | G13: 06 | H13: 02 | I13: 1 DAN | J13: Xxxxx Xxxxxx | K13: Xxxxxx. Kab. | L13: Xxxxxx | M13: approved | N13: LULUS
A14: 9 | B14: Kenshi 9 | C14: XX.X.XX.XX.XX.009 | D14: Male | E14: 21.6 | F14: 2004 | G14: 07 | H14: 04 | I14: 1 DAN | J14: Xxxxx Xxxxxx | K14: Xxxxxx. Kab. | L14: Xxxxxx | M14: approved | N14: LULUS
A15: 10 | B15: Kenshi 10 | C15: XX.X.XX.XX.XX.010 | D15: Male | E15: 26.76 | F15: 1999 | G15: 05 | H15: 09 | I15: 1 DAN | J15: Xxxxx Xxxxxx | K15: Xxxxxx. Kab. | L15: Xxxxxx | M15: approved | N15: LULUS
A16: 11 | B16: Kenshi 11 | C16: XX.X.XX.XX.XX.011 | D16: Male | E16: 26.76 | F16: 1999 | G16: 05 | H16: 09 | I16: 1 DAN | J16: Xxxxx Xxxxxx | K16: Xxxxxx. Kab. | L16: Xxxxxx | M16: approved | N16: LULUS | P16: atau Copas dari sini :
A17: 12 | B17: Kenshi 12 | C17: XX.X.XX.XX.XX.012 | D17: Male | E17: 49.75 | F17: 1976 | G17: 05 | H17: 19 | I17: 1 DAN | J17: Xxxxx Xxxxxx | K17: Xxxxxx. Kab. | L17: Xxxxxx | M17: approved | N17: LULUS
A18: 13 | B18: Kenshi 13 | C18: XX.X.XX.XX.XX.013 | D18: Male | E18: 31.7 | F18: 1994 | G18: 06 | H18: 02 | I18: 1 DAN | J18: Xxxxx Xxxxxx | K18: Xxxxxx. Kab. | L18: Xxxxxx | M18: approved | N18: LULUS | P18: LULUS
A19: 14 | B19: Kenshi 14 | C19: XX.X.XX.XX.XX.014 | D19: Male | E19: 49.75 | F19: 1976 | G19: 05 | H19: 19 | I19: 1 DAN | J19: Xxxxx Xxxxxx | K19: Xxxxxx. Kab. | L19: Xxxxxx | M19: approved | N19: LULUS | P19: TIDAK LULUS
A20: 15 | B20: Kenshi 15 | C20: XX.X.XX.XX.XX.015 | D20: Male | E20: 66.18 | F20: 1959 | G20: 12 | H20: 19 | I20: 1 DAN | J20: Xxxxx Xxxxxx | K20: Xxxxxx. Kota | L20: Xxxxxx | M20: approved | N20: LULUS | P20: TIDAK HADIR
A21: 16 | B21: Kenshi 16 | C21: XX.X.XX.XX.XX.016 | D21: Male | E21: 52.7 | F21: 1973 | G21: 06 | H21: 07 | I21: 1 DAN | J21: Xxxxx Xxxxxx | K21: Xxxxxx. Kota | L21: Xxxxxx | M21: approved | N21: LULUS
A22: 17 | B22: Kenshi 17 | C22: XX.X.XX.XX.XX.017 | D22: Male | E22: 29.18 | F22: 1996 | G22: 12 | H22: 08 | I22: 1 DAN | J22: Xxxxx Xxxxxx | K22: Xxxxxx. Kota | L22: Xxxxxx | M22: approved | N22: LULUS
A23: 18 | B23: Kenshi 18 | C23: XX.X.XX.XX.XX.018 | D23: Male | E23: 51.87 | F23: 1974 | G23: 04 | H23: 07 | I23: 1 DAN | J23: Xxxxx Xxxxxx | K23: Xxxxxx. Kota | L23: Xxxxxx | M23: approved | N23: LULUS | P23: Data peserta setelah terisi keterangan Lulus sesuai laporan hasil ujian (F-28), WAJIB diurutkan kembali berdasarkan urutan kolom Keterangan (urutkan dari dari LULUS sd TIDAK LULUS/TIDAK HADIR), dengan menggunakan fungsi Data --> Sort (sort by Column N). HANYA peserta yang LULUS saja yang akan ditampilkan pada Report WSKO.
A24: 19 | B24: Kenshi 19 | C24: XX.X.XX.XX.XX.019 | D24: Male | E24: 45 | F24: 1996 | G24: 12 | H24: 08 | I24: 1 DAN | J24: Xxxxx Xxxxxx | K24: Xxxxxx. Kota | L24: Xxxxxx | M24: approved | N24: LULUS
A25: 20 | B25: Kenshi 20 | C25: XX.X.XX.XX.XX.020 | D25: Female | E25: 49 | F25: 1974 | G25: 04 | H25: 07 | I25: 1 DAN | J25: Xxxxx Xxxxxx | K25: Xxxxxx. Kota | L25: Xxxxxx | M25: approved | N25: LULUS
A26: 21 | B26: Kenshi 21 | C26: XX.X.XX.XX.XX.021 | D26: Female | E26: 49.75 | F26: 1976 | G26: 05 | H26: 19 | I26: 1 DAN | J26: Xxxxx Xxxxxx | K26: Xxxxxx. Kab. | L26: Xxxxxx | M26: approved | N26: LULUS
A27: 22 | B27: Kenshi 22 | C27: XX.X.XX.XX.XX.022 | D27: Female | E27: 66.18 | F27: 1959 | G27: 12 | H27: 19 | I27: 1 DAN | J27: Xxxxx Xxxxxx | K27: Xxxxxx. Kota | L27: Xxxxxx | M27: approved | N27: LULUS
A28: 23 | B28: Kenshi 23 | C28: XX.X.XX.XX.XX.023 | D28: Female | E28: 52.7 | F28: 1973 | G28: 06 | H28: 07 | I28: 1 DAN | J28: Xxxxx Xxxxxx | K28: Xxxxxx. Kota | L28: Xxxxxx | M28: approved | N28: LULUS
A29: 24 | B29: Kenshi 24 | C29: XX.X.XX.XX.XX.024 | D29: Female | E29: 29.18 | F29: 1996 | G29: 12 | H29: 08 | I29: 1 DAN | J29: Xxxxx Xxxxxx | K29: Xxxxxx. Kota | L29: Xxxxxx | M29: approved | N29: LULUS
A30: 25 | B30: Kenshi 25 | C30: XX.X.XX.XX.XX.025 | D30: Female | E30: 51.87 | F30: 1974 | G30: 04 | H30: 07 | I30: 1 DAN | J30: Xxxxx Xxxxxx | K30: Xxxxxx. Kota | L30: Xxxxxx | M30: approved | N30: LULUS
A31: 26 | B31: Kenshi 26 | C31: XX.X.XX.XX.XX.026 | D31: Female | E31: 52.7 | F31: 1973 | G31: 06 | H31: 07 | I31: 1 DAN | J31: Xxxxx Xxxxxx | K31: Xxxxxx. Kota | L31: Xxxxxx | M31: approved | N31: LULUS
A32: 27 | B32: Kenshi 27 | C32: XX.X.XX.XX.XX.027 | D32: Female | E32: 66.18 | F32: 1959 | G32: 12 | H32: 19 | I32: 1 DAN | J32: Xxxxx Xxxxxx | K32: Xxxxxx. Kota | L32: Xxxxxx | M32: approved | N32: LULUS
A33: 28 | B33: Kenshi 28 | C33: XX.X.XX.XX.XX.028 | D33: Female | E33: 29.18 | F33: 1996 | G33: 12 | H33: 08 | I33: 1 DAN | J33: Xxxxx Xxxxxx | K33: Xxxxxx. Kota | L33: Xxxxxx | M33: approved | N33: LULUS
A34: 29 | B34: Kenshi 29 | C34: XX.X.XX.XX.XX.029 | D34: Female | E34: 51.87 | F34: 1974 | G34: 04 | H34: 07 | I34: 1 DAN | J34: Xxxxx Xxxxxx | K34: Xxxxxx. Kota | L34: Xxxxxx | M34: approved | N34: LULUS
A35: 30 | B35: Kenshi 30 | C35: XX.X.XX.XX.XX.030 | D35: Female | E35: 45 | F35: 1996 | G35: 12 | H35: 08 | I35: 1 DAN | J35: Xxxxx Xxxxxx | K35: Xxxxxx. Kota | L35: Xxxxxx | M35: approved | N35: LULUS
A36: 31 | B36: Kenshi 31 | C36: XX.X.XX.XX.XX.031 | D36: Female | E36: 49 | F36: 1974 | G36: 04 | H36: 07 | I36: 1 DAN | J36: Xxxxx Xxxxxx | K36: Xxxxxx. Kota | L36: Xxxxxx | M36: approved | N36: LULUS
A37: 32 | B37: Kenshi 32 | C37: XX.X.XX.XX.XX.032 | D37: Female | E37: 49 | F37: 1974 | G37: 04 | H37: 07 | I37: 1 DAN | J37: Xxxxx Xxxxxx | K37: Xxxxxx. Kota | L37: Xxxxxx | M37: approved | N37: LULUS
A38: 33 | B38: Kenshi 33 | C38: XX.X.XX.XX.XX.033 | D38: Female | E38: 66.18 | F38: 1959 | G38: 12 | H38: 19 | I38: 1 DAN | J38: Xxxxx Xxxxxx | K38: Xxxxxx. Kota | L38: Xxxxxx | M38: approved | N38: LULUS
A39: 34 | B39: Kenshi 34 | C39: XX.X.XX.XX.XX.034 | D39: Male | E39: 21.6 | F39: 2004 | G39: 07 | H39: 04 | I39: 1 DAN | J39: Xxxxx Xxxxxx | K39: Xxxxxx. Kab. | L39: Xxxxxx | M39: approved | N39: TIDAK LULUS
A40: 35 | B40: Kenshi 35 | C40: XX.X.XX.XX.XX.035 | D40: Male | E40: 26.76 | F40: 1999 | G40: 05 | H40: 09 | I40: 1 DAN | J40: Xxxxx Xxxxxx | K40: Xxxxxx. Kab. | L40: Xxxxxx | M40: approved | N40: TIDAK LULUS
A41: 36 | B41: Kenshi 36 | C41: XX.X.XX.XX.XX.036 | D41: Male | E41: 49.75 | F41: 1976 | G41: 05 | H41: 19 | I41: 1 DAN | J41: Xxxxx Xxxxxx | K41: Xxxxxx. Kab. | L41: Xxxxxx | M41: approved | N41: TIDAK HADIR
...

Sheet 1st DAN Report
B1: 昇段考試成績上申書 | I1: 支部名 Branch | J1: INDONESIA | Y1: JANGAN HAPUS INFO KOLOM DIBAWAH INI !
B2: Dan Examination Report | I2: Branch No | J2: 4 | K2: 1 | M2: 0 | N2: 0 | P2: 0 | R2: 1
B3: SHORINJI KEMPO UNITY 代表理事 宗 昂馬 様 | Y3: Note :
B4: To: Mr. Kouma So, Representative Director, Shorinji Kempo Unity | I4: Year | J4: 2026 | M4: / Month | P4: 2 | S4: / Day | U4: 10 | Y4: Tanggal yang diisi hanya pada baris ini, tanggal berikutnya otomatis akan terisi dengan tanggal yang sama.
B6: 昇段試験を実施した結果、下記の受験者が合格しましたので、成績を上申します。 | Y6: Isi dengan tanggal pembuatan laporan atau sama dengan tanggal pelantikan ujian
B7: After conducting the Dan Examination, the candidates listed below passed the examination, and we report the results.
B9: 考試日 Examination Date | F9: Year | G9: 2026 | H9: / Month | I9: 2 | J9: / Day | L9: 8 | Y9: Isi dengan tanggal pelantikan ujian
B11: No. | C11: 拳士コード Kenshi No. | F11: 受験資格 Applying Rank | I11: 宿題 Home Assignment | K11: 受験願書 Application Form | O11: 受験料 Exam Fee | S11: 技術 Techniques | V11: 学科 Philosophy
C12: 受験者氏名（ローマ字） Name of Applicant/s (in alphabetical order) | Y12: Kolom yang diisi hanya total nilai Teknik Ujian dan Nilai Paper/Makalah
B13: 1 | C13: =IF(AND('Data Dan'!$I$6="1 Dan",'Data Dan'!$N$6="LULUS"),VLOOKUP(B13,'Data Dan'!$A$6:$I$475,3,0),"") -> XX.X.XX.XX.XX.001 | H13: =_xlfn.IFNA(INDEX('Data Dan'!$I$6:$I$495,MATCH(C13,'Data Dan'!$C$6:$C$495,0)),"") -> 1 DAN | I13: =IF(AND(S13<>"",V13<>""),IF(V13>=90,"Excellent",IF(V13>=80,"Very Good",IF(V13>=70,"Good",IF(V13>=60,"Fair","Poor")))),"") -> Very Good | S13: 315 | V13: 87 | Y13: =_xlfn.IFNA(VLOOKUP(C13,'Data Dan'!$C$6:$N$995,12,0),"No Data") -> LULUS
L14: =IF(C13<>"","V","") -> V | P14: =IF(C13<>"","V","") -> V
C15: =_xlfn.IFNA(INDEX('Data Dan'!$B$6:$B$501,MATCH(C13,'Data Dan'!$C$6:$C$501,0)),"") -> Kenshi 1
B17: =B13+1 -> 2 | C17: =IF(AND('Data Dan'!$I$7="1 Dan",'Data Dan'!$N$7="LULUS"),VLOOKUP(B17,'Data Dan'!$A$6:$I$475,3,0),"") -> XX.X.XX.XX.XX.002 | H17: =_xlfn.IFNA(INDEX('Data Dan'!$I$6:$I$495,MATCH(C17,'Data Dan'!$C$6:$C$495,0)),"") -> 1 DAN | I17: =IF(AND(S17<>"",V17<>""),IF(V17>=90,"Excellent",IF(V17>=80,"Very Good",IF(V17>=70,"Good",IF(V17>=60,"Fair","Poor")))),"") -> Good | S17: 310 | V17: 75 | Y17: =_xlfn.IFNA(VLOOKUP(C17,'Data Dan'!$C$6:$N$995,12,0),"No Data") -> LULUS
L18: =IF(C17<>"","V","") -> V | P18: =IF(C17<>"","V","") -> V
C19: =_xlfn.IFNA(INDEX('Data Dan'!$B$6:$B$501,MATCH(C17,'Data Dan'!$C$6:$C$501,0)),"") -> Kenshi 2
B21: =B17+1 -> 3 | C21: =IF(AND('Data Dan'!$I$8="1 Dan",'Data Dan'!$N$8="LULUS"),VLOOKUP(B21,'Data Dan'!$A$6:$I$475,3,0),"") -> XX.X.XX.XX.XX.003 | H21: =_xlfn.IFNA(INDEX('Data Dan'!$I$6:$I$495,MATCH(C21,'Data Dan'!$C$6:$C$495,0)),"") -> 1 DAN | I21: =IF(AND(S21<>"",V21<>""),IF(V21>=90,"Excellent",IF(V21>=80,"Very Good",IF(V21>=70,"Good",IF(V21>=60,"Fair","Poor")))),"") | V21: 80 | Y21: =_xlfn.IFNA(VLOOKUP(C21,'Data Dan'!$C$6:$N$995,12,0),"No Data") -> LULUS
L22: =IF(C21<>"","V","") -> V | P22: =IF(C21<>"","V","") -> V
C23: =_xlfn.IFNA(INDEX('Data Dan'!$B$6:$B$501,MATCH(C21,'Data Dan'!$C$6:$C$501,0)),"") -> Kenshi 3
B25: =B21+1 -> 4 | C25: =IF(AND('Data Dan'!$I$9="1 Dan",'Data Dan'!$N$9="LULUS"),VLOOKUP(B25,'Data Dan'!$A$6:$I$475,3,0),"") -> XX.X.XX.XX.XX.004 | H25: =_xlfn.IFNA(INDEX('Data Dan'!$I$6:$I$495,MATCH(C25,'Data Dan'!$C$6:$C$495,0)),"") -> 1 DAN | I25: =IF(AND(S25<>"",V25<>""),IF(V25>=90,"Excellent",IF(V25>=80,"Very Good",IF(V25>=70,"Good",IF(V25>=60,"Fair","Poor")))),"") | Y25: =_xlfn.IFNA(VLOOKUP(C25,'Data Dan'!$C$6:$N$995,12,0),"No Data") -> LULUS
L26: =IF(C25<>"","V","") -> V | P26: =IF(C25<>"","V","") -> V
C27: =_xlfn.IFNA(INDEX('Data Dan'!$B$6:$B$501,MATCH(C25,'Data Dan'!$C$6:$C$501,0)),"") -> Kenshi 4
B29: =B25+1 -> 5 | C29: =IF(AND('Data Dan'!$I$10="1 Dan",'Data Dan'!$N$10="LULUS"),VLOOKUP(B29,'Data Dan'!$A$6:$I$475,3,0),"") -> XX.X.XX.XX.XX.005 | H29: =_xlfn.IFNA(INDEX('Data Dan'!$I$6:$I$495,MATCH(C29,'Data Dan'!$C$6:$C$495,0)),"") -> 1 DAN | I29: =IF(AND(S29<>"",V29<>""),IF(V29>=90,"Excellent",IF(V29>=80,"Very Good",IF(V29>=70,"Good",IF(V29>=60,"Fair","Poor")))),"") | Y29: =_xlfn.IFNA(VLOOKUP(C29,'Data Dan'!$C$6:$N$995,12,0),"No Data") -> LULUS
L30: =IF(C29<>"","V","") -> V | P30: =IF(C29<>"","V","") -> V
C31: =_xlfn.IFNA(INDEX('Data Dan'!$B$6:$B$501,MATCH(C29,'Data Dan'!$C$6:$C$501,0)),"") -> Kenshi 5
B33: =B29+1 -> 6 | C33: =IF(AND('Data Dan'!$I$11="1 Dan",'Data Dan'!$N$11="LULUS"),VLOOKUP(B33,'Data Dan'!$A$6:$I$475,3,0),"") -> XX.X.XX.XX.XX.006 | H33: =_xlfn.IFNA(INDEX('Data Dan'!$I$6:$I$495,MATCH(C33,'Data Dan'!$C$6:$C$495,0)),"") -> 1 DAN | I33: =IF(AND(S33<>"",V33<>""),IF(V33>=90,"Excellent",IF(V33>=80,"Very Good",IF(V33>=70,"Good",IF(V33>=60,"Fair","Poor")))),"") | Y33: =_xlfn.IFNA(VLOOKUP(C33,'Data Dan'!$C$6:$N$995,12,0),"No Data") -> LULUS
L34: =IF(C33<>"","V","") -> V | P34: =IF(C33<>"","V","") -> V
C35: =_xlfn.IFNA(INDEX('Data Dan'!$B$6:$B$501,MATCH(C33,'Data Dan'!$C$6:$C$501,0)),"") -> Kenshi 6
B37: =B33+1 -> 7 | C37: =IF(AND('Data Dan'!$I$12="1 Dan",'Data Dan'!$N$12="LULUS"),VLOOKUP(B37,'Data Dan'!$A$6:$I$475,3,0),"") -> XX.X.XX.XX.XX.007 | H37: =_xlfn.IFNA(INDEX('Data Dan'!$I$6:$I$495,MATCH(C37,'Data Dan'!$C$6:$C$495,0)),"") -> 1 DAN | I37: =IF(AND(S37<>"",V37<>""),IF(V37>=90,"Excellent",IF(V37>=80,"Very Good",IF(V37>=70,"Good",IF(V37>=60,"Fair","Poor")))),"") | Y37: =_xlfn.IFNA(VLOOKUP(C37,'Data Dan'!$C$6:$N$995,12,0),"No Data") -> LULUS
L38: =IF(C37<>"","V","") -> V | P38: =IF(C37<>"","V","") -> V
C39: =_xlfn.IFNA(INDEX('Data Dan'!$B$6:$B$501,MATCH(C37,'Data Dan'!$C$6:$C$501,0)),"") -> Kenshi 7
B41: =B37+1 -> 8 | C41: =IF(AND('Data Dan'!$I$13="1 Dan",'Data Dan'!$N$13="LULUS"),VLOOKUP(B41,'Data Dan'!$A$6:$I$475,3,0),"") -> XX.X.XX.XX.XX.008 | H41: =_xlfn.IFNA(INDEX('Data Dan'!$I$6:$I$495,MATCH(C41,'Data Dan'!$C$6:$C$495,0)),"") -> 1 DAN | I41: =IF(AND(S41<>"",V41<>""),IF(V41>=90,"Excellent",IF(V41>=80,"Very Good",IF(V41>=70,"Good",IF(V41>=60,"Fair","Poor")))),"") | Y41: =_xlfn.IFNA(VLOOKUP(C41,'Data Dan'!$C$6:$N$995,12,0),"No Data") -> LULUS
L42: =IF(C41<>"","V","") -> V | P42: =IF(C41<>"","V","") -> V
C43: =_xlfn.IFNA(INDEX('Data Dan'!$B$6:$B$501,MATCH(C41,'Data Dan'!$C$6:$C$501,0)),"") -> Kenshi 8
B45: =B41+1 -> 9 | C45: =IF(AND('Data Dan'!$I$14="1 Dan",'Data Dan'!$N$14="LULUS"),VLOOKUP(B45,'Data Dan'!$A$6:$I$475,3,0),"") -> XX.X.XX.XX.XX.009 | H45: =_xlfn.IFNA(INDEX('Data Dan'!$I$6:$I$495,MATCH(C45,'Data Dan'!$C$6:$C$495,0)),"") -> 1 DAN | I45: =IF(AND(S45<>"",V45<>""),IF(V45>=90,"Excellent",IF(V45>=80,"Very Good",IF(V45>=70,"Good",IF(V45>=60,"Fair","Poor")))),"") | Y45: =_xlfn.IFNA(VLOOKUP(C45,'Data Dan'!$C$6:$N$995,12,0),"No Data") -> LULUS
L46: =IF(C45<>"","V","") -> V | P46: =IF(C45<>"","V","") -> V
C47: =_xlfn.IFNA(INDEX('Data Dan'!$B$6:$B$501,MATCH(C45,'Data Dan'!$C$6:$C$501,0)),"") -> Kenshi 9
B49: =B45+1 -> 10 | C49: =IF(AND('Data Dan'!$I$15="1 Dan",'Data Dan'!$N$15="LULUS"),VLOOKUP(B49,'Data Dan'!$A$6:$I$475,3,0),"") -> XX.X.XX.XX.XX.010 | H49: =_xlfn.IFNA(INDEX('Data Dan'!$I$6:$I$495,MATCH(C49,'Data Dan'!$C$6:$C$495,0)),"") -> 1 DAN | I49: =IF(AND(S49<>"",V49<>""),IF(V49>=90,"Excellent",IF(V49>=80,"Very Good",IF(V49>=70,"Good",IF(V49>=60,"Fair","Poor")))),"") | Y49: =_xlfn.IFNA(VLOOKUP(C49,'Data Dan'!$C$6:$N$995,12,0),"No Data") -> LULUS
L50: =IF(C49<>"","V","") -> V | P50: =IF(C49<>"","V","") -> V
C51: =_xlfn.IFNA(INDEX('Data Dan'!$B$6:$B$501,MATCH(C49,'Data Dan'!$C$6:$C$501,0)),"") -> Kenshi 10
C54: 支部長氏名 | I54: 署名
...

Sheet Masterdata
A1: Referensi Pengisian Data Laporan menuju DAN
A3: Item | B3: Nilai | C3: Deskripsi Nilai | D3: Pengertian
A4: Home Assignment | B4: 90 - 100 | C4: Excellent | D4: Istimewa
A5: (Makalah/Paper) | B5: 80 - 89 | C5: Very Good | D5: Baik Sekali
B6: 70 - 79 | C6: Good | D6: Baik
B7: 60 - 69 | C7: Fair | D7: Cukup
B8: 50 - 59 | C8: Poor | D8: Kurang
A10: Techniques | B10: 270 - 400 | C10: Gabungan total nilai Teknik Dasar, Teknik Pilihan, Embu dan Unyo Ho
A12: Philosophy | B12: 70 - 100 | C12: Nilai ujian tertulis/teori
A13: (Ujian Tertulis/Wawancara)
