Workbook

Sheet 8 KYU
A1: FORMULIR - 27
A2: FORMULIR PENILAIAN UJIAN KENAIKAN TINGKAT MENUJU KYU VIII (DELAPAN)
A3: Tanggal :
A4: NO. | B4: NAMA | C4: N.I.K | D4: DOJO / PENGKAB / PENGKOT / PENGPROV | E4: JENIS KELAMIN | F4: UMUR | G4: TEKNIK I | L4: TEKNIK II | R4: HOKEI SO TAI | V4: Nilai Total
G5: 100 | L5: 100 | R5: 100
G6: Etika - Tata Krama | H6: Tai Gamae | I6: Tai Sabaki | J6: Umpo Ho | K6: Sub Total | L6: Teknik Menyerang | M6: Teknik Bertahan | N6: Bertahan dgn Bergerak | O6: Do Zuki, Do Geri | P6: Ken (tandoku) | Q6: Sub Total | R6: Uchi uke zuki (ura) | S6: Kote nuki | T6: Tenchi ken dai ikkei (tandoku) | U6: Sub Total
G7: 40 | H7: 20 | I7: 20 | J7: 20 | K7: 100 | L7: 20 | M7: 20 | N7: 10 | O7: 10 | P7: 40 | Q7: 100 | R7: 30 | S7: 30 | T7: 40 | U7: 100 | V7: 300
A8: 1
A9: =A8+1 -> 2
A10: =A9+1 -> 3
A11: =A10+1 -> 4
A12: =A11+1 -> 5
A13: =A12+1 -> 6
A14: =A13+1 -> 7
A15: =A14+1 -> 8
A16: =A15+1 -> 9
A17: =A16+1 -> 10
A19: Teknik I (100) : | F19: Teknik II (100) : | R19: Hokei So Tai (100) :
A20: 1. | B20: Etika-Tatakrama : Evaluasi selama ujian Penguji dapat menguji dengan memerintahkan peserta ujian | F20: 1. | G20: Teknik Menyerang : (kaisoku dachi) me uchi, furiko zuki (hidari mae, migi mae) jun zuki, gyaku zuki | R20: Lakukan sisi kanan saja.
B21: untuk mengerjakan soal-soal ini.
A22: 2. | B22: Tai gamae, bentuknya : (kaisoku, hidari, migi) chudan gamae, ichiji gamae, tai gamae, hiraki gamae. | F22: 2. | G22: Teknik Bertahan : (kaisoku dachi) uchi uke, uchi harai uke
A23: 3. | B23: Tai sabaki : zen tenkan, han tenkan, kaishin. | F23: 3. | G23: Bertahan dengan bergerak : zenshin zuki (jun, gyaku), zenshin geri (jun, gyaku)
A24: 4. | B24: Umpo ho : chidori ashi, kani ashi, juji ashi, kumo ashi. | F24: 4. | G24: Kihon hokei : dilakukan dari kedua sisi kiri (10 poin) dan sisi kanan (10 poin)
A26: Catatan : Ujian teknik terdiri dari Teknik I (100 poin), Teknik II (100 poin) dan Hokei (100 poin). Setiap kategori harus 60% dari 100 poin dan juga skor total harus 70% dari 300 poin untuk lulus tes.
B28: Penguji 1 | E28: Penguji 2 | Q28: Penguji 3
B32: Nama : | E32: Nama : | Q32: Nama :
B33: DAN : | E33: DAN : | Q33: DAN :
A35: 11
A36: =A35+1 -> 12
A37: =A36+1 -> 13
A38: =A37+1 -> 14
A39: =A38+1 -> 15
A40: =A39+1 -> 16
A41: =A40+1 -> 17
A42: =A41+1 -> 18
A43: =A42+1 -> 19
A44: =A43+1 -> 20
A46: Teknik I (100) : | F46: Teknik II (100) : | R46: Hokei So Tai (100) :
A47: 1. | B47: Etika-Tatakrama : Evaluasi selama ujian Penguji dapat menguji dengan memerintahkan peserta ujian | F47: 1. | G47: Teknik Menyerang : (kaisoku dachi) me uchi, furiko zuki (hidari mae, migi mae) jun zuki, gyaku zuki | R47: Lakukan sisi kanan saja.
B48: untuk mengerjakan soal-soal ini.
...

Sheet 7 KYU
A1: FORMULIR - 27
A2: FORMULIR PENILAIAN UJIAN KENAIKAN TINGKAT MENUJU KYU VII (TUJUH)
A3: Tanggal :
A4: NO. | B4: NAMA | C4: N.I.K | D4: DOJO / PENGKAB / PENGKOT / PENGPROV | E4: JENIS KELAMIN | F4: UMUR | G4: TEKNIK I | M4: TEKNIK II | S4: HOKEI SO TAI | Y4: Nilai Total
G5: 100 | M5: 100 | S5: 100
G6: Etika - Tata Krama | H6: Tai Gamae | I6: Tai Sabaki | J6: Umpo Ho | K6: Ukemi | L6: Sub Total | M6: Teknik Menyerang | N6: Teknik Bertahan | O6: Bertahan dgn Bergerak | P6: Do Zuki, Do Geri | Q6: Ken (tandoku) | R6: Sub Total | S6: Uwa uke zuki (omote) | T6: Uchi uke zuki (ura) | U6: Kote nuki | V6: Ryuo ken dai ikkei (tandoku) | W6: - | X6: Sub Total
G7: 60 | H7: 10 | I7: 10 | J7: 10 | K7: 10 | L7: 100 | M7: 20 | N7: 20 | O7: 10 | P7: 10 | Q7: 40 | R7: 100 | S7: 20 | T7: 20 | U7: 20 | V7: 40 | X7: 100 | Y7: 300
A8: 1
A9: =A8+1 -> 2
A10: =A9+1 -> 3
A11: =A10+1 -> 4
A12: =A11+1 -> 5
A13: =A12+1 -> 6
A14: =A13+1 -> 7
A15: =A14+1 -> 8
A16: =A15+1 -> 9
A17: =A16+1 -> 10
A19: Teknik I (100) : | F19: Teknik II (100) : | S19: Hokei So Tai (100) :
A20: 1. | B20: Etika-Tatakrama : Evaluasi selama ujian Penguji dapat menguji dengan memerintahkan peserta ujian | F20: 1. | G20: Teknik Menyerang : (kaisoku dachi) me uchi, kinteki geri, furiko zuki, keri age, (hidari mae, migi mae) jun zuki, gyaku zuki, jun geri, gyaku geri | S20: Lakukan kedua sisi untuk evaluasi keseluruhan.
B21: untuk mengerjakan soal-soal ini. | S21: Untuk teknik Goho gunakan alat pelindung (Do).
A22: 2. | B22: Tai gamae, bentuknya : (kaisoku, hidari, migi) chudan gamae, ichiji gamae, tai gamae, hiraki gamae. | F22: 2. | G22: Teknik Bertahan : (kaisoku dachi) uwa uke, uchi uke, shita uke, uchi harai uke
A23: 3. | B23: Tai sabaki : zen tenkan, han tenkan. | F23: 3. | G23: Bertahan dengan bergerak : zenshin zuki (jun, gyaku), zenshin geri (jun, gyaku)
A24: 4. | B24: Umpo ho : chidori ashi, kani ashi, juji ashi, kumo ashi. | F24: 4. | G24: Do zuki, do geri: (kaisoku dachi) furiko zuki, keri age, (hidari mae, migi mae) jun zuki, gyaku zuki, jun geri, gyaku geri
A25: 5. | B25: Ukemi : mae ukemi, ushiro ukemi, daisharin, oten yori okiagari.
F26: 5. | G26: Kihon hokei : dilakukan dari kedua sisi kiri (10 poin) dan sisi kanan (10 poin)
A27: Catatan : Ujian teknik terdiri dari Teknik I (100 poin), Teknik II (100 poin) dan Hokei (100 poin). Setiap kategori harus 60% dari 100 poin dan juga skor total harus 70% dari 300 poin untuk lulus tes.
B29: Penguji 1 | E29: Penguji 2 | R29: Penguji 3
B33: Nama : | E33: Nama : | R33: Nama :
B34: DAN : | E34: DAN : | R34: DAN :
A36: 11
A37: =A36+1 -> 12
A38: =A37+1 -> 13
A39: =A38+1 -> 14
A40: =A39+1 -> 15
A41: =A40+1 -> 16
A42: =A41+1 -> 17
A43: =A42+1 -> 18
A44: =A43+1 -> 19
A45: =A44+1 -> 20
A47: Teknik I (100) : | F47: Teknik II (100) : | S47: Hokei So Tai (100) :
...

Sheet 6 KYU
A1: FORMULIR - 27
A2: FORMULIR PENILAIAN UJIAN KENAIKAN TINGKAT MENUJU KYU VI (ENAM)
A3: Tanggal :
A4: NO. | B4: NAMA | C4: N.I.K | D4: DOJO / PENGKAB / PENGKOT / PENGPROV | E4: JENIS KELAMIN | F4: UMUR | G4: TEKNIK I | M4: TEKNIK II | T4: HOKEI SO TAI | Z4: Nilai Total
G5: 100 | M5: 100 | T5: 100
G6: Etika - Tata Krama | H6: Tai Gamae | I6: Tai Sabaki | J6: Umpo Ho | K6: Ukemi | L6: Sub Total | M6: Teknik Menyerang | N6: Teknik Bertahan | O6: Bertahan dgn Bergerak | P6: Do Zuki, Do Geri | Q6: Tenchi ken dai ikkei (tandoku) | R6: Ryuo ken dai ikkei (tandoku) | S6: Sub Total | T6: Ryu sui geri (ushiro) | U6: Uchi uke zuki (ura) | V6: Tenshin geri | W6: Uwa uke zuki (omote) | X6: Kote nuki | Y6: Sub Total
G7: 60 | H7: 10 | I7: 10 | J7: 10 | K7: 10 | L7: 100 | M7: 20 | N7: 20 | O7: 10 | P7: 10 | Q7: 20 | R7: 20 | S7: 100 | T7: 20 | U7: 20 | V7: 20 | W7: 20 | X7: 20 | Y7: 100 | Z7: 300
A8: 1
A9: =A8+1 -> 2
A10: =A9+1 -> 3
A11: =A10+1 -> 4
A12: =A11+1 -> 5
A13: =A12+1 -> 6
A14: =A13+1 -> 7
A15: =A14+1 -> 8
A16: =A15+1 -> 9
A17: =A16+1 -> 10
A19: Teknik I (100) : | F19: Teknik II (100) : | T19: Hokei So Tai (100) :
A20: 1. | B20: Etika-Tatakrama : Evaluasi selama ujian Penguji dapat menguji dengan memerintahkan peserta ujian | F20: 1. | G20: Teknik Menyerang : (kaisoku dachi) me uchi, kinteki geri, furiko zuki, keri age, (hidari mae, migi mae) jun zuki, gyaku zuki, jun geri, gyaku geri | T20: Lakukan kedua sisi untuk evaluasi keseluruhan.
B21: untuk mengerjakan soal-soal ini. | T21: Untuk teknik Goho gunakan alat pelindung (Do).
A22: 2. | B22: Tai gamae, bentuknya : (kaisoku, hidari, migi) chudan gamae, ichiji gamae, tai gamae, hiraki gamae. | F22: 2. | G22: Teknik Bertahan : (kaisoku dachi) uwa uke, uchi uke, shita uke, uchi harai uke
A23: 3. | B23: Tai sabaki : zen tenkan, han tenkan. | F23: 3. | G23: Bertahan dengan bergerak : zenshin zuki (jun, gyaku), zenshin geri (jun, gyaku)
A24: 4. | B24: Umpo ho : chidori ashi, kani ashi, juji ashi, kumo ashi. | F24: 4. | G24: Do zuki, do geri: (kaisoku dachi) furiko zuki, keri age, (hidari mae, migi mae) jun zuki, gyaku zuki, jun geri, gyaku geri
A25: 5. | B25: Ukemi : mae ukemi, ushiro ukemi, daisharin, oten yori okiagari.
F26: 5. | G26: Kihon hokei : dilakukan dari kedua sisi kiri (10 poin) dan sisi kanan (10 poin)
A27: Catatan : Ujian teknik terdiri dari Teknik I (100 poin), Teknik II (100 poin) dan Hokei (100 poin). Setiap kategori harus 60% dari 100 poin dan juga skor total harus 70% dari 300 poin untuk lulus tes.
B29: Penguji 1 | E29: Penguji 2 | R29: Penguji 3
B33: Nama : | E33: Nama : | R33: Nama :
B34: DAN : | E34: DAN : | R34: DAN :
A36: 11
A37: =A36+1 -> 12
A38: =A37+1 -> 13
A39: =A38+1 -> 14
A40: =A39+1 -> 15
A41: =A40+1 -> 16
A42: =A41+1 -> 17
A43: =A42+1 -> 18
A44: =A43+1 -> 19
A45: =A44+1 -> 20
A47: Teknik I (100) : | F47: Teknik II (100) : | T47: Hokei So Tai (100) :
...

Sheet 5 KYU
A1: FORMULIR - 27
A2: FORMULIR PENILAIAN UJIAN KENAIKAN TINGKAT MENUJU KYU V (LIMA)
A3: Tanggal :
A4: NO. | B4: NAMA | C4: N.I.K | D4: DOJO / PENGKAB / PENGKOT / PENGPROV | E4: JENIS KELAMIN | F4: UMUR | G4: TEKNIK I | M4: TEKNIK II | V4: HOKEI SO TAI | AG4: Nilai Total
G5: 100 | M5: 100 | V5: 100
G6: Etika - Tata Krama | H6: Tai Gamae | I6: Tai Sabaki | J6: Umpo Ho | K6: Ukemi | L6: Sub Total | M6: Teknik Menyerang 1 | N6: Teknik Menyerang 2 | O6: Teknik Bertahan | P6: Bertahan dgn Bergerak | Q6: Do Zuki, Do Geri | R6: Tenchi ken dai ikkei (tandoku) | S6: Ryuo ken dai ikkei (tandoku) | T6: Giwa ken dai ikkei (tandoku) | U6: Sub Total | V6: Tenchi ken dai ikkei (pasangan) | W6: Ryuo ken dai ikkei (pasangan) | X6: Ryusui geri (mae) | Y6: Uwa uke zuki (ura) | Z6: Uwa uke geri (omote, ura) | AA6: Shita uke geri | AB6: Shita uke jun geri | AC6: Katate yori nuki | AD6: Maki nuki (katate) | AE6: Gyaku gote - mae yubi gatame | AF6: Sub Total
G7: 20 | H7: 20 | I7: 20 | J7: 20 | K7: 20 | L7: 100 | M7: 10 | N7: 10 | O7: 10 | P7: 10 | Q7: 10 | R7: 20 | S7: 20 | T7: 10 | U7: 100 | V7: 10 | W7: 10 | X7: 10 | Y7: 10 | Z7: 10 | AA7: 10 | AB7: 10 | AC7: 10 | AD7: 10 | AE7: 10 | AF7: 100 | AG7: 300
A8: 1
A9: =A8+1 -> 2
A10: =A9+1 -> 3
A11: =A10+1 -> 4
A12: =A11+1 -> 5
A13: =A12+1 -> 6
A14: =A13+1 -> 7
A15: =A14+1 -> 8
A16: =A15+1 -> 9
A17: =A16+1 -> 10
A19: Teknik I (100) : | F19: Teknik II (100) : | V19: Hokei So Tai (100) :
A20: 1. | B20: Etika-Tatakrama : Evaluasi selama ujian Penguji dapat menguji dengan memerintahkan peserta ujian | F20: 1. | G20: Teknik Menyerang 1 : (kaisoku dachi) me uchi, kinteki geri, furiko zuki, gedan zuki, shuto uchi, keri age, jo chu ni ren zuki. | V20: Lakukan kedua sisi untuk evaluasi keseluruhan.
B21: untuk mengerjakan soal-soal ini. | V21: Untuk teknik Goho gunakan alat pelindung (Do).
A22: 2. | B22: Tai gamae, bentuknya : (kaisoku, hidari, migi) chudan gamae, ichiji gamae, tai gamae, hiraki gamae. | F22: 2. | G22: Teknik Menyerang 2 : (hidari mae, migi mae) jun zuki, gyaku zuki, jun geri, gyaku geri, sashikomi mawashi geri.
A23: 3. | B23: Tai sabaki : zen tenkan, han tenkan.
A24: 4. | B24: Umpo ho : chidori ashi, kani ashi, juji ashi, kumo ashi. | F24: 3. | G24: Teknik Bertahan : (kaisoku dachi) uwa uke, uchi uke, shita uke, uchi harai uke
A25: 5. | B25: Ukemi : mae ukemi, ushiro ukemi, daisharin, oten yori okiagari. | F25: 4. | G25: Bertahan dengan bergerak : zenshin zuki (jun, gyaku), zenshin geri (jun, gyaku), hiraki sagatte jun geri.
F26: 5. | G26: Do zuki, do geri : (kaisoku dachi) furiko zuki, keri age, (hidari mae, migi mae) jun zuki, gyaku zuki, jun geri, gyaku geri.
A28: Catatan : Ujian teknik terdiri dari Teknik I (100 poin), Teknik II (100 poin) dan Hokei (100 poin). Setiap kategori harus 60% dari 100 poin dan juga skor total harus 70% dari 300 poin untuk lulus tes.
B30: Penguji 1 | F30: Penguji 2 | V30: Penguji 3
B34: Nama : | F34: Nama : | V34: Nama :
B35: DAN : | F35: DAN : | V35: DAN :
A37: 11
A38: =A37+1 -> 12
A39: =A38+1 -> 13
A40: =A39+1 -> 14
A41: =A40+1 -> 15
A42: =A41+1 -> 16
A43: =A42+1 -> 17
A44: =A43+1 -> 18
A45: =A44+1 -> 19
A46: =A45+1 -> 20
A47: Teknik I (100) : | F47: Teknik II (100) : | V47: Hokei So Tai (100) :
...

Sheet 4 KYU
A1: FORMULIR - 27
A2: FORMULIR PENILAIAN UJIAN KENAIKAN TINGKAT MENUJU KYU IV (EMPAT)
A3: Tanggal :
A4: NO. | B4: NAMA | C4: N.I.K | D4: DOJO / PENGKAB / PENGKOT / PENGPROV | E4: JENIS KELAMIN | F4: UMUR | G4: TEKNIK I | M4: TEKNIK II | X4: HOKEI SO TAI | AI4: Nilai Total
G5: 100 | M5: 100 | X5: 100
G6: Etika - Tata Krama | H6: Tai Gamae | I6: Tai Sabaki | J6: Umpo Ho | K6: Ukemi | L6: Sub Total | M6: Teknik Menyerang 1 | N6: Teknik Menyerang 2 | O6: Teknik Bertahan | P6: Bertahan dgn Bergerak | Q6: Bertahan & Menyerang Bergerak | R6: Tenchi ken dai ikkei & dai nikei (tandoku) | S6: Tenchi ken dai ikkei (pasangan) | T6: Ryuo ken dai ikkei (tandoku) | U6: Ryuo ken dai ikkei (pasangan) | V6: Giwa ken dai ikkei (tandoku) | W6: Sub Total | X6: Soto uke zuki (ura, omote) | Y6: Soto uke geri (ura, omote) | Z6: Uchi age zuki (ura, omote) | AA6: Uchi age geri (ura, omote) | AB6: Tsuki nuki (soto) | AC6: Tsuki nuki (uchi) | AD6: Kiri nuki (soto) | AE6: Kiri nuki (uchi) | AF6: Katate okuri gote - okuri gatame | AG6: Okuri maki tembin | AH6: Sub Total
G7: 20 | H7: 20 | I7: 20 | J7: 20 | K7: 20 | L7: 100 | M7: 10 | N7: 10 | O7: 10 | P7: 10 | Q7: 10 | R7: 10 | S7: 10 | T7: 10 | U7: 10 | V7: 10 | W7: 100 | X7: 10 | Y7: 10 | Z7: 10 | AA7: 10 | AB7: 10 | AC7: 10 | AD7: 10 | AE7: 10 | AF7: 10 | AG7: 10 | AH7: 100 | AI7: 300
A8: 1
A9: =A8+1 -> 2
A10: =A9+1 -> 3
A11: =A10+1 -> 4
A12: =A11+1 -> 5
A13: =A12+1 -> 6
A14: =A13+1 -> 7
A15: =A14+1 -> 8
A16: =A15+1 -> 9
A17: =A16+1 -> 10
A19: Teknik I (100) : | G19: Teknik II (100) : | Y19: Hokei So Tai (100) :
A20: 1. | B20: Etika-Tatakrama : Evaluasi selama ujian Penguji dapat menguji dengan memerintahkan peserta ujian | G20: 1. | H20: Teknik Menyerang 1 : (kaisoku dachi) me uchi, kinteki geri, furiko zuki, gedan zuki, shuto uchi, keri age, jo chu ni ren zuki. | Y20: Lakukan kedua sisi untuk evaluasi keseluruhan.
B21: untuk mengerjakan soal-soal ini. | Y21: Untuk teknik Goho gunakan alat pelindung (Do).
B22: (1) shuho, seiretsu, cara duduk, cara berdiri, kesshu, gassho rei | G22: 2. | H22: Teknik Menyerang 2 : (hidari mae, migi mae) jun zuki, gyaku zuki, jun geri, gyaku geri, sashikomi mawashi geri.
B23: (2) chosoku, happo moku, pakaian, sikap, tanggapan, bahasa.
A24: 2. | B24: Tai gamae : chudan gamae, hasso gamae, ichiji gamae. | G24: 3. | H24: Teknik Bertahan : (kaisoku dachi) uwa uke, uchi uke, shita uke, uchi harai uke
A25: 3. | B25: Tai sabaki : zen tenkan, han tenkan, jun sagari, hiraki sagari. | G25: 4. | H25: Bertahan dengan bergerak : zenshin zuki (jun, gyaku), zenshin geri (jun, gyaku), hiraki sagatte jun geri.
A26: 4. | B26: Umpo ho : chidori ashi, kani ashi, juji ashi, kumo ashi. | G26: 5. | H26: Do zuki, do geri : (kaisoku dachi) furiko zuki, keri age, (hidari mae, migi mae) jun zuki, gyaku zuki, jun geri, gyaku geri.
A27: 5. | B27: Ukemi : mae ukemi, ushiro ukemi, daisharin, oten yori okiagari.
A28: Catatan : Ujian teknik terdiri dari Teknik I (100 poin), Teknik II (100 poin) dan Hokei (100 poin). Setiap kategori harus 60% dari 100 poin dan juga skor total harus 70% dari 300 poin untuk lulus tes.
B30: Penguji 1 | F30: Penguji 2 | AA30: Penguji 3
B34: Nama : | F34: Nama : | AA34: Nama :
B35: DAN : | F35: DAN : | AA35: DAN :
A37: 11
A38: =A37+1 -> 12
A39: =A38+1 -> 13
A40: =A39+1 -> 14
A41: =A40+1 -> 15
A42: =A41+1 -> 16
A43: =A42+1 -> 17
A44: =A43+1 -> 18
A45: =A44+1 -> 19
A46: =A45+1 -> 20
...

Sheet 3 KYU
A1: FORMULIR - 27
A2: FORMULIR PENILAIAN UJIAN KENAIKAN TINGKAT MENUJU KYU III (TIGA)
A3: Tanggal :
A4: NO. | B4: NAMA | C4: N.I.K | D4: DOJO / PENGKAB / PENGKOT / PENGPROV | E4: JENIS KELAMIN | F4: UMUR | G4: TEKNIK DASAR | N4: TEKNIK PILIHAN | X4: KUMI EMBU | Z4: Nilai Total A | AB4: PENERAPAN TEKNIK | AD4: Nilai Total B | AE4: Nilai Total
G5: 100 | N5: 100 | AB5: 100
G6: Tai Gamae-Tai Sabaki-Umpo Ho | H6: Ukemi | I6: Teknik Menyerang | J6: Teknik Bertahan | K6: Bertahan & Menyerang Bergerak | L6: Ken (tandoku) | M6: Ken (so tai) | N6: Goho (50) | S6: Juho (50) | X6: 100 | AB6: Goho (50) | AC6: Juho (50)
X7: Ketepatan | Y7: Penampilan | AB7: Bertahan, serangan balasan, semangat, sikap, bertahan dan menyerang bergantian | AC7: Bertahan, serangan balasan, semangat, sikap, bertahan dan menyerang bergantian
G8: 10 | H8: 10 | I8: 10 | J8: 10 | K8: 10 | L8: 40 | M8: 10 | N8: 10 | O8: 10 | P8: 10 | Q8: 10 | R8: 10 | S8: 10 | T8: 10 | U8: 10 | V8: 10 | W8: 10 | X8: 60 | Y8: 40 | Z8: 300 | AB8: 50 | AC8: 50 | AD8: 100 | AE8: 400
A9: 1
A10: =A9+1 -> 2
A11: =A10+1 -> 3
A12: =A11+1 -> 4
A13: =A12+1 -> 5
A14: =A13+1 -> 6
A15: =A14+1 -> 7
A16: =A15+1 -> 8
A17: =A16+1 -> 9
A18: =A17+1 -> 10
A19: TEKNIK DASAR (100) : | N19: KUMI EMBU (100) : | AB19: Penyerang & bertahan ditentukan Penguji.
A20: 1. | B20: Tai gamae : chudan gamae, hasso gamae, ichiji gamae | D20: 6. Kihon hokei (solo) : tenchi ken dai ikkei sampai dai yonkei (kiri, kanan) | N20: 1. | O20: Tenchi ken dai ikkei (so tai)
B21: Tai sabaki : zen tenkan, han tenkan, jun sagari, hiraki sagari | D21: ryuo ken dai ikkei (kiri, kanan), giwa ken dai nikei | N21: 2. | O21: Ryusui geri (ushiro) | AB21: Goho
B22: Umpo ho : chidori ashi, kani ashi, juji ashi, kumo ashi | D22: 7. Kihon hokei (pasangan) : tenchi ken dai ikkei, giwa ken dai ikkei. | N22: 3. | O22: Ryote yori nuki | AB22: Penyerang : serangan tunggal/ganda, zuki/keri.
A23: 2. | B23: Ukemi : mae ukemi, ushiro ukemi, daisharin, oten yori okiagari | N23: 4. | O23: Ryuo ken dai ikkei (so tai) | AB23: Bertahan : merespon dengan serangan balasan.
A24: 3. | B24: Teknik Menyerang : (kaisoku dachi) furiko zuki, shuto uchi, kumade zuki, keri age (kiri, kanan) jo chu ni ren zuki, jo chu mawashi geri, sashikomi mawashi geri, sashikae sokuto geri | N24: 5. | O24: Uwa uke zuki (omote)
D25: TEKNIK PILIHAN (100) : | N25: 6. | O25: Gyaku gote ~ mae yubi gatame | AB25: Juho
AB26: Penyerang : memegang pergelangan/lengan.
A27: 4. | B27: Teknik Bertahan : kaisoku dachi, bertahan dengan serangan balik masuk ( ), uwa uke (tsuki), uchi uke (tsuki), shita uke (keri), soto uke (tsuki), uchi age uke (keri), uchi harai uke (keri) | D27: Catatan untuk Teknik Pilihan: | N27: Catatan untuk Kumi Embu: | AB27: Bertahan : teknik ryuo ken, ryuka ken & rakan ken.
D28: Paling sedikit 3 teknik masing-masing goho & juho merupakan waza Kyu 3. | N28: Seorang peserta ujian menampilkan (1), (3), (5)
D29: Teknik dilakukan dari sisi kanan & sisi kiri. | N29: & peserta lain menampilkan (2), (4), (6)
A30: 5. | B30: Bertahan dan Menyerang saat Bergerak : zenshin zuki (jun, gyaku), zenshin geri (jun, gyaku), hiraki sagatte jun geri | N30: Penguji menentukan siapa yang memulai terlebih dahulu.
A32: (1) Ujian teknik terdiri dari Kategori A [Teknik Dasar (100), Teknik Pilihan (100), Kumi Embu (100), dan Kategori B [Penerapan Teknik (100)]. Total Kategori A harus 70% dari 300 poin dan Kategori B harus 70% dari 100 poin untuk lulus ujian.
A33: (2) Jika Kategori A atau B kurang dari 70% dari 300 poin, hasilnya adalah Tidak Lulus. Meskipun total Kategori A mencapai skor kelulusan, jika salah satu teknik dasar, teknik pilihan atau kumi embu tidak mencapai 60% dari 100 poin, hasil ujiannya tidak lulus.
B35: Penguji 1 | F35: Penguji 2 | Y35: Penguji 3
B39: Nama : | F39: Nama : | Y39: Nama :
B40: DAN : | F40: DAN : | Y40: DAN :
A42: 11
A43: =A42+1 -> 12
A44: =A43+1 -> 13
A45: =A44+1 -> 14
A46: =A45+1 -> 15
...

Sheet 3 KYU (Hal 2)
A1: FORMULIR - 27
A2: PENILAIAN KUMI EMBU (PAIRED EMBU) MENUJU KYU III (TIGA)
A3: Tanggal :
A4: NO | B4: NAMA | C4: Ketepatan (60) | J4: Penampilan (40) | O4: Total Embu | Q4: Catatan Penguji
C5: Goho: Serangan, pertahanan, serangan balasan, 5 elemen atemi, dll. Juho: Bertahan, menghindar, melepas, menekuk pergelangan, bantingan, kuncian | I5: Sub Total | J5: 1. Komposisi, Irama dan Moderasi | K5: 2. Kuda-kuda, sikap dan keindahan | L5: 3. Kihaku (semangat), Kiai, Sae (jelas) | M5: 4. Chosoku (pernafasan), Mekubari (Perhatian), dan Zanshin | N5: Sub Total
C7: 1 | D7: 2 | E7: 3 | F7: 4 | G7: 5 | H7: 6 | J7: 1 | K7: 2 | L7: 3 | M7: 4
C8: 10 | D8: 10 | E8: 10 | F8: 10 | G8: 10 | H8: 10 | I8: 60 | J8: 10 | K8: 10 | L8: 10 | M8: 10 | N8: 40 | O8: 100
A9: 1 | B9: ='3 KYU'!B9 -> 0 | R9: Fokus Penilaian Penguji
A10: 2 | B10: ='3 KYU'!B10 -> 0 | Q10: Ketepatan | R10: Penilaian setiap komposisi dengan titik fokus yang tercantum di bawah ini. - Goho: serangan, pertahanan, serangan balasan, 5 elemen atemi, dll. - Juho: shuho, nuki-waza, gyaku-waza, katame-waza, masing-masing prinsip, dll. Evaluasi tidak hanya kecepatan atau tampilan yang menarik, tetapi lihat apakah elemen-elemen tekniknya disusun dengan benar dan prinsip-prinsip diterapkan, untuk mengevaluasi esensi teknik tersebut. Lihat juga apakah gerakannya memiliki unsur bela diri dan masuk akal dari sudut pandang bela diri.
A11: 3 | B11: ='3 KYU'!B11 -> 0
A12: 4 | B12: ='3 KYU'!B12 -> 0
A13: 5 | B13: ='3 KYU'!B13 -> 0
A14: 6 | B14: ='3 KYU'!B14 -> 0
A15: 7 | B15: ='3 KYU'!B15 -> 0 | Q15: Penampilan | R15: 1 | S15: Komposisi, Irama, dan Moderasi | Y15: 1. Terdiri dari teknik sesuai dengan tingkatannya. 2. Tidak ada keraguan dalam melakukan rangkaian tehnik. 3. Tidak ada gerakan yang tidak perlu pada perubahan posisi dan gerakan, dll.
A16: 8 | B16: ='3 KYU'!B16 -> 0
A17: 9 | B17: ='3 KYU'!B17 -> 0
A18: 10 | B18: ='3 KYU'!B18 -> 0
A19: Embu Berpasangan | G19: Perhatian! | R19: 2 | S19: Kuda-kuda, sikap, dan keindahan | Y19: 1. Relaks 2. Postur tubuh yang baik 3. Posisi kaki, posisi pinggul rendah, posisi kepalan tangan baik dan tangan ditekan ke samping.
A20: 1. | B20: Tenchi ken dai ikkei (so tai) | G20: - Seorang peserta ujian menampilkan (1), (3), (5)
A21: 2. | B21: Ryusui geri (ushiro) | G21: & peserta lain menampilkan (2), (4), (6)
A22: 3. | B22: Ryote yori nuki | G22: - Penguji menentukan siapa yang memulai terlebih dahulu.
A23: 4. | B23: Ryuo ken dai ikkei (so tai) | G23: - Penguji mengevaluasi setiap peserta ujian. | R23: 3 | S23: Kihaku (semangat), Kiai, Sae (jelas) | Y23: 1.Terlihat, kihaku (bersemangat) 2. Kecepatan, kekuatan, kime, dll.
A24: 5. | B24: Uwa uke zuki (omote) | G24: - Jika peserta ujian tidak mengingat urutan embu dan penguji harus memberitahunya, setiap pemberitahuan mengurangi 2 poin dari komposisi, irama dan moderasi.
A25: 5. | B25: Gyaku gote ~ mae yubi gatame
R26: 4 | S26: Chosoku (pernafasan), Mekubari (Perhatian), dan Zanshin | Y26: 1. Ada tidak ada gangguan pernapasan. 2. Tatapan mata pada lawan. 3. Kesiapan fisik dan mental setelah teknik, dll.
B31: Penguji 1 | J31: Penguji 2 | W31: Penguji 3
B35: Nama : | J35: Nama : | W35: Nama :
B36: DAN : | J36: DAN : | W36: DAN :
A38: 11 | B38: ='3 KYU'!B42 -> 0 | R38: Fokus Penilaian Penguji
A39: =A38+1 -> 12 | B39: ='3 KYU'!B43 -> 0 | Q39: Ketepatan | R39: Penilaian setiap komposisi dengan titik fokus yang tercantum di bawah ini. - Goho: serangan, pertahanan, serangan balasan, 5 elemen atemi, dll. - Juho: shuho, nuki-waza, gyaku-waza, katame-waza, masing-masing prinsip, dll. Evaluasi tidak hanya kecepatan atau tampilan yang menarik, tetapi lihat apakah elemen-elemen tekniknya disusun dengan benar dan prinsip-prinsip diterapkan, untuk mengevaluasi esensi teknik tersebut. Lihat juga apakah gerakannya memiliki unsur bela diri dan masuk akal dari sudut pandang bela diri.
A40: =A39+1 -> 13 | B40: ='3 KYU'!B44 -> 0
A41: =A40+1 -> 14 | B41: ='3 KYU'!B45 -> 0
A42: =A41+1 -> 15 | B42: ='3 KYU'!B46 -> 0
A43: =A42+1 -> 16 | B43: ='3 KYU'!B47 -> 0
A44: =A43+1 -> 17 | B44: ='3 KYU'!B48 -> 0 | Q44: Penampilan | R44: 1 | S44: Komposisi, Irama, dan Moderasi | Y44: 1. Terdiri dari teknik sesuai dengan tingkatannya. 2. Tidak ada keraguan dalam melakukan rangkaian tehnik. 3. Tidak ada gerakan yang tidak perlu pada perubahan posisi dan gerakan, dll.
A45: =A44+1 -> 18 | B45: ='3 KYU'!B49 -> 0
A46: =A45+1 -> 19 | B46: ='3 KYU'!B50 -> 0
A47: =A46+1 -> 20 | B47: ='3 KYU'!B51 -> 0
A48: Embu Berpasangan | G48: Perhatian! | R48: 2 | S48: Kuda-kuda, sikap, dan keindahan | Y48: 1. Relaks 2. Postur tubuh yang baik 3. Posisi kaki, posisi pinggul rendah, posisi kepalan tangan baik dan tangan ditekan ke samping.
A49: 1. | B49: Tenchi ken dai ikkei (so tai) | G49: - Seorang peserta ujian menampilkan (1), (3), (5)
...

Sheet 2 KYU
A1: FORMULIR - 27
A2: FORMULIR PENILAIAN UJIAN KENAIKAN TINGKAT MENUJU KYU II (DUA)
A3: Tanggal :
A4: NO. | B4: NAMA | C4: N.I.K | D4: DOJO / PENGKAB / PENGKOT / PENGPROV | E4: JENIS KELAMIN | F4: UMUR | G4: TEKNIK DASAR | N4: TEKNIK PILIHAN | X4: KUMI EMBU | Z4: Nilai Total A | AB4: PENERAPAN TEKNIK | AD4: Nilai Total B | AE4: Nilai Total
G5: 100 | N5: 100 | AB5: 100
G6: Tai Gamae-Tai Sabaki-Umpo Ho | H6: Ukemi | I6: Teknik Menyerang | J6: Teknik Bertahan | K6: Bertahan & Menyerang Bergerak | L6: Ken (tandoku) | M6: Ken (so tai) | N6: Goho (50) | S6: Juho (50) | X6: 100 | AB6: Goho (50) | AC6: Juho (50)
X7: Ketepatan | Y7: Penampilan | AB7: Bertahan, serangan balasan, semangat, sikap, bertahan dan menyerang bergantian | AC7: Bertahan, serangan balasan, semangat, sikap, bertahan dan menyerang bergantian
G8: 10 | H8: 10 | I8: 10 | J8: 10 | K8: 10 | L8: 40 | M8: 10 | N8: 10 | O8: 10 | P8: 10 | Q8: 10 | R8: 10 | S8: 10 | T8: 10 | U8: 10 | V8: 10 | W8: 10 | X8: 60 | Y8: 40 | Z8: 300 | AB8: 50 | AC8: 50 | AD8: 100 | AE8: 400
A9: 1
A10: =A9+1 -> 2
A11: =A10+1 -> 3
A12: =A11+1 -> 4
A13: =A12+1 -> 5
A14: =A13+1 -> 6
A15: =A14+1 -> 7
A16: =A15+1 -> 8
A17: =A16+1 -> 9
A18: =A17+1 -> 10
A19: TEKNIK DASAR (100) : | N19: KUMI EMBU (100) : | AB19: Penyerang & bertahan ditentukan Penguji.
A20: 1. | B20: Tai gamae : chudan gamae, hasso gamae, ichiji gamae | D20: shita uke, jo chu ni ren zuki, ren uke (pasangan). | N20: 1. | O20: Tsuki ten ichi ren han ko
B21: Tai sabaki : zen tenkan, han tenkan, jun sagari, hiraki sagari | D21: 6. Kihon hokei (solo) : tenchi ken dai ikkei sampai dai yonkei (kiri, kanan) | N21: 2. | O21: Han tenshin geri ren han ko | AB21: Goho
B22: Umpo ho : chidori ashi, kani ashi, juji ashi, kumo ashi | D22: ryuo ken dai ikkei (hidari, migi), giwa ken dai nikei | N22: 3. | O22: Okuri gote (katate) ~ okuri yoko tembin ~ ura gatame | AB22: Penyerang : serangan tunggal/ganda, zuki/keri.
A23: 2. | B23: Ukemi : mae ukemi, ushiro ukemi, daisharin, oten yori okiagari | D23: 7. Kihon hokei (pasangan) : tenchi ken dai ikkei, giwa ken dai ikkei. | N23: 4. | O23: Kiri gote (katate) | AB23: Bertahan : merespon dengan serangan balasan.
A24: 3. | B24: Teknik Menyerang : (kaisoku dachi) furiko zuki, shuto uchi, kumade zuki, keri age (kiri, kanan) jo chu ni ren zuki, jo chu mawashi geri, sashikomi mawashi geri, sashikae sokuto geri | N24: 5. | O24: Tenchi ken dai nikei (so tai)
N25: 6. | O25: Johaku dori (ryote) | AB25: Juho
D26: TEKNIK PILIHAN (100) : | AB26: Penyerang : memegang pergelangan/lengan.
A27: 4. | B27: Teknik Bertahan : kaisoku dachi, bertahan dengan serangan balik masuk ( ), uwa uke (tsuki), uchi uke (tsuki), shita uke (keri), soto uke (tsuki), uchi age uke (keri), uchi harai uke (keri) | N27: Catatan untuk Kumi Embu: | AB27: Bertahan : teknik ryuo ken, ryuka ken & rakan ken.
D28: Catatan untuk Teknik Pilihan: | N28: Seorang peserta ujian menampilkan (1), (3), (5)
D29: Paling sedikit 3 teknik masing-masing goho & juho merupakan waza Kyu 2. | N29: & peserta lain menampilkan (2), (4), (6)
A30: 5. | B30: Bertahan dan Menyerang saat Bergerak : zenshin zuki (jun, gyaku), zenshin geri (jun, gyaku), hiraki sagatte jun geri (solo), chudan zuki, | D30: Teknik dilakukan dari sisi kanan & sisi kiri. | N30: Penguji menentukan siapa yang memulai terlebih dahulu.
A32: (1) Ujian teknik terdiri dari Kategori A [Teknik Dasar (100), Teknik Pilihan (100), Kumi Embu (100), dan Kategori B [Penerapan Teknik (100)]. Total Kategori A harus 70% dari 300 poin dan Kategori B harus 70% dari 300 poin untuk lulus ujian.
A33: (2) Jika Kategori A atau B kurang dari 70% dari 300 poin, hasilnya adalah Tidak Lulus. Meskipun total Kategori A mencapai skor kelulusan, jika salah satu teknik dasar, teknik pilihan atau kumi embu tidak mencapai 60% dari 100 poin, hasil ujiannya tidak lulus.
B35: Penguji 1 | F35: Penguji 2 | Y35: Penguji 3
B39: Nama : | F39: Nama : | Y39: Nama :
B40: DAN : | F40: DAN : | Y40: DAN :
A42: 11
A43: =A42+1 -> 12
A44: =A43+1 -> 13
A45: =A44+1 -> 14
A46: =A45+1 -> 15
...

Sheet 2 KYU (Hal 2)
A1: FORMULIR - 27
A2: PENILAIAN KUMI EMBU (PAIRED EMBU) MENUJU KYU II (DUA)
A3: Tanggal :
A4: NO | B4: NAMA | C4: Ketepatan (60) | J4: Penampilan (40) | O4: Total Embu | Q4: Catatan Penguji
C5: Goho: Serangan, pertahanan, serangan balasan, 5 elemen atemi, dll. Juho: Bertahan, menghindar, melepas, menekuk pergelangan, bantingan, kuncian | I5: Sub Total | J5: 1. Komposisi, Irama dan Moderasi | K5: 2. Kuda-kuda, sikap dan keindahan | L5: 3. Kihaku (semangat), Kiai, Sae (jelas) | M5: 4. Chosoku (pernafasan), Mekubari (Perhatian), dan Zanshin | N5: Sub Total
C7: 1 | D7: 2 | E7: 3 | F7: 4 | G7: 5 | H7: 6 | J7: 1 | K7: 2 | L7: 3 | M7: 4
C8: 10 | D8: 10 | E8: 10 | F8: 10 | G8: 10 | H8: 10 | I8: 60 | J8: 10 | K8: 10 | L8: 10 | M8: 10 | N8: 40 | O8: 100
A9: 1 | B9: ='2 KYU'!B9 -> 0 | R9: Fokus Penilaian Penguji
A10: 2 | B10: ='2 KYU'!B10 -> 0 | Q10: Ketepatan | R10: Penilaian setiap komposisi dengan titik fokus yang tercantum di bawah ini. - Goho: serangan, pertahanan, serangan balasan, 5 elemen atemi, dll. - Juho: shuho, nuki-waza, gyaku-waza, katame-waza, masing-masing prinsip, dll. Evaluasi tidak hanya kecepatan atau tampilan yang menarik, tetapi lihat apakah elemen-elemen tekniknya disusun dengan benar dan prinsip-prinsip diterapkan, untuk mengevaluasi esensi teknik tersebut. Lihat juga apakah gerakannya memiliki unsur bela diri dan masuk akal dari sudut pandang bela diri.
A11: 3 | B11: ='2 KYU'!B11 -> 0
A12: 4 | B12: ='2 KYU'!B12 -> 0
A13: 5 | B13: ='2 KYU'!B13 -> 0
A14: 6 | B14: ='2 KYU'!B14 -> 0
A15: 7 | B15: ='2 KYU'!B15 -> 0 | Q15: Penampilan | R15: 1 | S15: Komposisi, Irama, dan Moderasi | Y15: 1. Terdiri dari teknik sesuai dengan tingkatannya. 2. Tidak ada keraguan dalam melakukan rangkaian tehnik. 3. Tidak ada gerakan yang tidak perlu pada perubahan posisi dan gerakan, dll.
A16: 8 | B16: ='2 KYU'!B16 -> 0
A17: 9 | B17: ='2 KYU'!B17 -> 0
A18: 10 | B18: ='2 KYU'!B18 -> 0
A19: Embu Berpasangan | G19: Perhatian! | R19: 2 | S19: Kuda-kuda, sikap, dan keindahan | Y19: 1. Relaks 2. Postur tubuh yang baik 3. Posisi kaki, posisi pinggul rendah, posisi kepalan tangan baik dan tangan ditekan ke samping.
A20: 1. | B20: Tsuki ten ichi ren han ko | G20: - Seorang peserta ujian menampilkan (1), (3), (5)
A21: 2. | B21: Han tenshin geri ren han ko | G21: & peserta lain menampilkan (2), (4), (6)
A22: 3. | B22: Okuri gote (katate) ~ okuri yoko tembin ~ ura gatame | G22: - Penguji menentukan siapa yang memulai terlebih dahulu.
A23: 4. | B23: Kiri gote (katate) | G23: - Penguji mengevaluasi setiap peserta ujian. | R23: 3 | S23: Kihaku (semangat), Kiai, Sae (jelas) | Y23: 1.Terlihat, kihaku (bersemangat) 2. Kecepatan, kekuatan, kime, dll.
A24: 5. | B24: Tenchi ken dai nikei (so tai) | G24: - Jika peserta ujian tidak mengingat urutan embu dan penguji harus memberitahunya, setiap pemberitahuan mengurangi 2 poin dari komposisi, irama dan moderasi.
A25: 6. | B25: Johaku dori (ryote)
R26: 4 | S26: Chosoku (pernafasan), Mekubari (Perhatian), dan Zanshin | Y26: 1. Ada tidak ada gangguan pernapasan. 2. Tatapan mata pada lawan. 3. Kesiapan fisik dan mental setelah teknik, dll.
B31: Penguji 1 | J31: Penguji 2 | W31: Penguji 3
B35: Nama : | J35: Nama : | W35: Nama :
B36: DAN : | J36: DAN : | W36: DAN :
A38: 11 | B38: ='2 KYU'!B42 -> 0 | R38: Fokus Penilaian Penguji
A39: =A38+1 -> 12 | B39: ='2 KYU'!B43 -> 0 | Q39: Ketepatan | R39: Penilaian setiap komposisi dengan titik fokus yang tercantum di bawah ini. - Goho: serangan, pertahanan, serangan balasan, 5 elemen atemi, dll. - Juho: shuho, nuki-waza, gyaku-waza, katame-waza, masing-masing prinsip, dll. Evaluasi tidak hanya kecepatan atau tampilan yang menarik, tetapi lihat apakah elemen-elemen tekniknya disusun dengan benar dan prinsip-prinsip diterapkan, untuk mengevaluasi esensi teknik tersebut. Lihat juga apakah gerakannya memiliki unsur bela diri dan masuk akal dari sudut pandang bela diri.
A40: =A39+1 -> 13 | B40: ='2 KYU'!B44 -> 0
A41: =A40+1 -> 14 | B41: ='2 KYU'!B45 -> 0
A42: =A41+1 -> 15 | B42: ='2 KYU'!B46 -> 0
A43: =A42+1 -> 16 | B43: ='2 KYU'!B47 -> 0
A44: =A43+1 -> 17 | B44: ='2 KYU'!B48 -> 0 | Q44: Penampilan | R44: 1 | S44: Komposisi, Irama, dan Moderasi | Y44: 1. Terdiri dari teknik sesuai dengan tingkatannya. 2. Tidak ada keraguan dalam melakukan rangkaian tehnik. 3. Tidak ada gerakan yang tidak perlu pada perubahan posisi dan gerakan, dll.
A45: =A44+1 -> 18 | B45: ='2 KYU'!B49 -> 0
A46: =A45+1 -> 19 | B46: ='2 KYU'!B50 -> 0
A47: =A46+1 -> 20 | B47: ='2 KYU'!B51 -> 0
A48: Embu Berpasangan | G48: Perhatian! | R48: 2 | S48: Kuda-kuda, sikap, dan keindahan | Y48: 1. Relaks 2. Postur tubuh yang baik 3. Posisi kaki, posisi pinggul rendah, posisi kepalan tangan baik dan tangan ditekan ke samping.
A49: 1. | B49: Tsuki ten ichi ren han ko | G49: - Seorang peserta ujian menampilkan (1), (3), (5)
...

Sheet 1 KYU
A1: FORMULIR - 27
A2: FORMULIR PENILAIAN KENAIKAN TINGKAT MENUJU KYU I (SATU)
A3: Tanggal :
A4: NO. | B4: NAMA | C4: N.I.K | D4: DOJO / PENGKAB / PENGKOT / PENGPROV | E4: JENIS KELAMIN | F4: UMUR | G4: TEKNIK DASAR | N4: TEKNIK PILIHAN | X4: KUMI EMBU | Z4: Nilai Total A | AB4: PENERAPAN TEKNIK | AD4: Nilai Total B | AE4: Nilai Total
G5: 100 | N5: 100 | AB5: 100
G6: Tai Gamae-Tai Sabaki-Umpo Ho | H6: Ukemi | I6: Teknik Menyerang | J6: Teknik Bertahan | K6: Bertahan & Menyerang Bergerak | L6: Ken (tandoku) | M6: Ken (so tai) | N6: Goho (50) | S6: Juho (50) | X6: 100 | AB6: Goho (50) | AC6: Juho (50)
X7: Ketepatan | Y7: Penampilan | AB7: Bertahan, serangan balasan, semangat, sikap, bertahan dan menyerang bergantian | AC7: Bertahan, serangan balasan, semangat, sikap, bertahan dan menyerang bergantian
G8: 10 | H8: 10 | I8: 10 | J8: 10 | K8: 10 | L8: 40 | M8: 10 | N8: 10 | O8: 10 | P8: 10 | Q8: 10 | R8: 10 | S8: 10 | T8: 10 | U8: 10 | V8: 10 | W8: 10 | X8: 60 | Y8: 40 | Z8: 300 | AB8: 50 | AC8: 50 | AD8: 100 | AE8: 400
A9: 1
A10: =A9+1 -> 2
A11: =A10+1 -> 3
A12: =A11+1 -> 4
A13: =A12+1 -> 5
A14: =A13+1 -> 6
A15: =A14+1 -> 7
A16: =A15+1 -> 8
A17: =A16+1 -> 9
A18: =A17+1 -> 10
A19: TEKNIK DASAR (100) : | N19: KUMI EMBU (100) : | AB19: Penyerang & bertahan ditentukan Penguji.
A20: 1. | B20: Tai gamae : chudan gamae, hasso gamae, ichiji gamae | D20: shita uke, jo chu ni ren zuki, ren uke (pasangan). | N20: 1. | O20: Tsubame gaeshi ren han ko
B21: Tai sabaki : zen tenkan, han tenkan, jun sagari, hiraki sagari | D21: 6. Kihon hokei (solo) : tenchi ken dai ikkei sampai dai yonkei (kiri, kanan) | N21: 2. | O21: Soto oshi uke zuki ren han ko | AB21: Goho
B22: Umpo ho : chidori ashi, kani ashi, juji ashi, kumo ashi | D22: ryuo ken dai ikkei (hidari, migi), giwa ken dai nikei | N22: 3. | O22: Eri juji | AB22: Penyerang : tsuki & keri ke arah jodan & chudan
A23: 2. | B23: Ukemi : mae ukemi, ushiro ukemi, daisharin, oten yori okiagari | D23: 7. Kihon hokei (pasangan) : tenchi ken dai ikkei, giwa ken dai ikkei | N23: 4. | O23: Sode maki | AB23: Bertahan : merespon dengan serangan balasan.
A24: 3. | B24: Teknik Menyerang : (kaisoku dachi) furiko zuki, shuto uchi, kumade zuki, keri age (kiri, kanan) jo chu ni ren zuki, jo chu mawashi geri, sashikomi mawashi geri, sashikae sokuto geri | N24: 5. | O24: Tsuki ten san ren han ko
N25: 6. | O25: Maki gote (morote) ~ tembin gatame (ura) | AB25: Juho
D26: TEKNIK PILIHAN (100) : | AB26: Penyerang : memegang pergelangan/lengan.
A27: 4. | B27: Teknik Bertahan : kaisoku dachi, bertahan dengan serangan balik masuk ( ), uwa uke (tsuki), uchi uke (tsuki), shita uke (keri), soto uke (tsuki), uchi age uke (keri), uchi harai uke (keri) | N27: Catatan untuk Kumi Embu: | AB27: Bertahan : teknik gyaku atau nuki.
D28: Catatan untuk Teknik Pilihan: | N28: Seorang peserta ujian menampilkan (1), (3), (5)
D29: Paling sedikit 3 teknik masing-masing goho & juho merupakan waza Kyu 1. | N29: & peserta lain menampilkan (2), (4), (6)
A30: 5. | B30: Bertahan dan Menyerang saat Bergerak : zenshin zuki (jun, gyaku), zenshin geri (jun, gyaku), hiraki sagatte jun geri (solo), chudan zuki, | D30: Teknik dilakukan dari sisi kanan & sisi kiri. | N30: Penguji menentukan siapa yang memulai terlebih dahulu.
A32: (1) Ujian teknik terdiri dari Kategori A [Teknik Dasar (100), Teknik Pilihan (100), Kumi Embu (100), dan Kategori B [Penerapan Teknik (100)]. Total Kategori A harus 70% dari 300 poin dan Kategori B harus 70% dari 300 poin untuk lulus ujian.
A33: (2) Jika Kategori A atau B kurang dari 70% dari 300 poin, hasilnya adalah Tidak Lulus. Meskipun total Kategori A mencapai skor kelulusan, jika salah satu teknik dasar, teknik pilihan atau kumi embu tidak mencapai 60% dari 100 poin, hasil ujiannya tidak lulus.
B35: Penguji 1 | F35: Penguji 2 | Y35: Penguji 3
B39: Nama : | F39: Nama : | Y39: Nama :
B40: DAN : | F40: DAN : | Y40: DAN :
A42: 11
A43: =A42+1 -> 12
A44: =A43+1 -> 13
A45: =A44+1 -> 14
A46: =A45+1 -> 15
...

Sheet 1 KYU (Hal 2)
A1: FORMULIR - 27
A2: PENILAIAN KUMI EMBU (PAIRED EMBU) MENUJU KYU I (SATU)
A3: Tanggal : | Y3: Nama Penguji :
A4: NO | B4: NAMA | C4: Ketepatan (60) | J4: Penampilan (40) | O4: Total Embu | Q4: Catatan Penguji
C5: Goho: Serangan, pertahanan, serangan balasan, 5 elemen atemi, dll. Juho: Bertahan, menghindar, melepas, menekuk pergelangan, bantingan, kuncian | I5: Sub Total | J5: 1. Komposisi, Irama dan Moderasi | K5: 2. Kuda-kuda, sikap dan keindahan | L5: 3. Kihaku (semangat), Kiai, Sae (jelas) | M5: 4. Chosoku (pernafasan), Mekubari (Perhatian), dan Zanshin | N5: Sub Total
C7: 1 | D7: 2 | E7: 3 | F7: 4 | G7: 5 | H7: 6 | J7: 1 | K7: 2 | L7: 3 | M7: 4
C8: 10 | D8: 10 | E8: 10 | F8: 10 | G8: 10 | H8: 10 | I8: 60 | J8: 10 | K8: 10 | L8: 10 | M8: 10 | N8: 40 | O8: 100
A9: 1 | B9: ='1 KYU'!B9 -> 0 | R9: Fokus Penilaian Penguji
A10: 2 | B10: ='1 KYU'!B10 -> 0 | Q10: Ketepatan | R10: Penilaian setiap komposisi dengan titik fokus yang tercantum di bawah ini. - Goho: serangan, pertahanan, serangan balasan, 5 elemen atemi, dll. - Juho: shuho, nuki-waza, gyaku-waza, katame-waza, masing-masing prinsip, dll. Evaluasi tidak hanya kecepatan atau tampilan yang menarik, tetapi lihat apakah elemen-elemen tekniknya disusun dengan benar dan prinsip-prinsip diterapkan, untuk mengevaluasi esensi teknik tersebut. Lihat juga apakah gerakannya memiliki unsur bela diri dan masuk akal dari sudut pandang bela diri.
A11: 3 | B11: ='1 KYU'!B11 -> 0
A12: 4 | B12: ='1 KYU'!B12 -> 0
A13: 5 | B13: ='1 KYU'!B13 -> 0
A14: 6 | B14: ='1 KYU'!B14 -> 0
A15: 7 | B15: ='1 KYU'!B15 -> 0 | Q15: Penampilan | R15: 1 | S15: Komposisi, Irama, dan Moderasi | Y15: 1. Terdiri dari teknik sesuai dengan tingkatannya. 2. Tidak ada keraguan dalam melakukan rangkaian tehnik. 3. Tidak ada gerakan yang tidak perlu pada perubahan posisi dan gerakan, dll.
A16: 8 | B16: ='1 KYU'!B16 -> 0
A17: 9 | B17: ='1 KYU'!B17 -> 0
A18: 10 | B18: ='1 KYU'!B18 -> 0
A19: Embu Berpasangan | G19: Perhatian! | R19: 2 | S19: Kuda-kuda, sikap, dan keindahan | Y19: 1. Relaks 2. Postur tubuh yang baik 3. Posisi kaki, posisi pinggul rendah, posisi kepalan tangan baik dan tangan ditekan ke samping.
A20: 1. | B20: Tsubame gaeshi ren han ko | G20: - Seorang peserta ujian menampilkan (1), (3), (5)
A21: 2. | B21: Soto oshi uke zuki ren han ko | G21: & peserta lain menampilkan (2), (4), (6)
A22: 3. | B22: Eri juji | G22: - Penguji menentukan siapa yang memulai terlebih dahulu.
A23: 4. | B23: Sode maki | G23: - Penguji mengevaluasi setiap peserta ujian. | R23: 3 | S23: Kihaku (semangat), Kiai, Sae (jelas) | Y23: 1.Terlihat, kihaku (bersemangat) 2. Kecepatan, kekuatan, kime, dll.
A24: 5. | B24: Tsuki ten san ren han ko | G24: - Jika peserta ujian tidak mengingat urutan embu dan penguji harus memberitahunya, setiap pemberitahuan mengurangi 2 poin dari komposisi, irama dan moderasi.
A25: 6. | B25: Maki gote (morote) ~ tembin gatame (ura)
R26: 4 | S26: Chosoku (pernafasan), Mekubari (Perhatian), dan Zanshin | Y26: 1. Ada tidak ada gangguan pernapasan. 2. Tatapan mata pada lawan. 3. Kesiapan fisik dan mental setelah teknik, dll.
B31: Penguji 1 | J31: Penguji 2 | W31: Penguji 3
B35: Nama : | J35: Nama : | W35: Nama :
B36: DAN : | J36: DAN : | W36: DAN :
A38: 11 | B38: ='1 KYU'!B42 -> 0 | R38: Fokus Penilaian Penguji
A39: =A38+1 -> 12 | B39: ='1 KYU'!B43 -> 0 | Q39: Ketepatan | R39: Penilaian setiap komposisi dengan titik fokus yang tercantum di bawah ini. - Goho: serangan, pertahanan, serangan balasan, 5 elemen atemi, dll. - Juho: shuho, nuki-waza, gyaku-waza, katame-waza, masing-masing prinsip, dll. Evaluasi tidak hanya kecepatan atau tampilan yang menarik, tetapi lihat apakah elemen-elemen tekniknya disusun dengan benar dan prinsip-prinsip diterapkan, untuk mengevaluasi esensi teknik tersebut. Lihat juga apakah gerakannya memiliki unsur bela diri dan masuk akal dari sudut pandang bela diri.
A40: =A39+1 -> 13 | B40: ='1 KYU'!B44 -> 0
A41: =A40+1 -> 14 | B41: ='1 KYU'!B45 -> 0
A42: =A41+1 -> 15 | B42: ='1 KYU'!B46 -> 0
A43: =A42+1 -> 16 | B43: ='1 KYU'!B47 -> 0
A44: =A43+1 -> 17 | B44: ='1 KYU'!B48 -> 0 | Q44: Penampilan | R44: 1 | S44: Komposisi, Irama, dan Moderasi | Y44: 1. Terdiri dari teknik sesuai dengan tingkatannya. 2. Tidak ada keraguan dalam melakukan rangkaian tehnik. 3. Tidak ada gerakan yang tidak perlu pada perubahan posisi dan gerakan, dll.
A45: =A44+1 -> 18 | B45: ='1 KYU'!B49 -> 0
A46: =A45+1 -> 19 | B46: ='1 KYU'!B50 -> 0
A47: =A46+1 -> 20 | B47: ='1 KYU'!B51 -> 0
A48: Embu Berpasangan | G48: Perhatian! | R48: 2 | S48: Kuda-kuda, sikap, dan keindahan | Y48: 1. Relaks 2. Postur tubuh yang baik 3. Posisi kaki, posisi pinggul rendah, posisi kepalan tangan baik dan tangan ditekan ke samping.
A49: 1. | B49: Tsubame gaeshi ren han ko | G49: - Seorang peserta ujian menampilkan (1), (3), (5)
...

Sheet 1 DAN
A1: FORMULIR-27
A2: FORMULIR PENILAIAN KENAIKAN TINGKAT MENUJU DAN I (SATU)
A3: Tanggal :
A4: NO. | B4: NAMA | C4: N.I.K | D4: DOJO / PENGKAB / PENGKOT / PENGPROV | E4: Jenis Kelamin | F4: Umur | G4: Tehnik Dasar (100) | O4: Tehnik Pilihan (100) | Z4: Kumi Embu (100) | AC4: Nilai Total A | AE4: Penerapan Tehnik/Unyo-ho (100) | AG4: Nilai Total B | AH4: Nilai Total
G5: Tai gamae, Tai sabaki, Umpo ho | H5: Ukemi | I5: Teknik Dasar Serangan | J5: Teknik Dasar Bertahan | K5: Menyerang dan bertahan sambil bergerak | L5: Tan'en kihon hokei | M5: Tan'en kihon hokei (Berpasangan) | N5: Total | O5: Goho (50) | T5: Juho (50) | Y5: Total | Z5: Ketepatan | AA5: Penampilan | AB5: Sub Total | AE5: Goho (50) | AF5: Juho (50)
AE6: Bertahan, serangan balasan, semangat, sikap, bertahan dan menyerang bergantian | AF6: Bertahan, serangan balasan, semangat, sikap, bertahan dan menyerang bergantian
G7: 10 | H7: 10 | I7: 10 | J7: 10 | K7: 10 | L7: 20 | M7: 30 | N7: 100 | O7: 10 | P7: 10 | Q7: 10 | R7: 10 | S7: 10 | T7: 10 | U7: 10 | V7: 10 | W7: 10 | X7: 10 | Y7: 100 | Z7: 50 | AA7: 50 | AB7: 100 | AC7: 300 | AE7: 50 | AF7: 50 | AG7: 100 | AH7: 400
A8: 1
A9: =A8+1 -> 2
A10: =A9+1 -> 3
A11: =A10+1 -> 4
A12: =A11+1 -> 5
A13: =A12+1 -> 6
A14: =A13+1 -> 7
A15: =A14+1 -> 8
A16: =A15+1 -> 9
A17: =A16+1 -> 10
A18: Teknik Dasar (100): | E18: 5 | F18: Offenses while moving: zenshin zuki (jo chu ni ren zuki, | O18: Kumi Embu (100): | AE18: Unyo-ho(100) : (Wajib hingga usia 49 tahun)
A19: 1 | B19: Tai gamae: chudan gamae, hasso gamae, ichiji gamae | F19: jo chu mawashi geri), hiraki sagatte ren uke | O19: 1 | P19: Harai uke geri ke tsuki ten san | AE19: Penyerang & bertahan ditentukan Penguji.
B20: - tai sabaki: zen tenkan, han tenkan, jun sagari, hiraki sagari | E20: 6 | F20: Tan'en kihon hokei: tenchi ken dai ikkei through dai rokkei (left, right) | P20: Bertahan : melakukan harai uke geri dan jo chu jo san ren zuki | AE20: 1. Goho
B21: - umpo ho: chidori ashi, kani ashi, juji ashi, kumo ashi | F21: ryuo ken dai ikkei (left, right), giwa ken dai ikkei & dai nikei | O21: 2 | P21: Gyaku geri hiza uke nami gaeshi ke tsuki ten ichi | AE21: Penyerang: tsuki dan keri ke jodan atau chudan.
A22: 2 | B22: Ukemi: mae ukemi, ushiro ukemi, daisharin, oten yori okiagari | F22: byakuren ken dai ikkei | P22: Bertahan : melakukan gyaku geri hiza uke nami gaeshi dan jo chu ni ren zuki | AE22: Bertahan: serangan balasan bebas
A23: 3 | B23: Dasar menyerang: (kaisoku dachi) furiko zuki, shuto uchi, kumade zuki, keri age, | E23: 7 | F23: Tan'en kihon hokei (paired): tenchi ken dai ikkei & dai nikei | O23: 3 | P23: Morote kiri gote, Penyerang: ude ushiro neji age | AE23: 2. Juho
B24: - (hidari mae, migi mae) jo chu ni ren zuki, jo chu mawashi geri, ren geri, sashikae sokuto geri | F24: giwa ken dai ikkei, ryuo ken dai ikkei | O24: 4 | P24: Morote oshi nuki, Penyerang: gyaku tembin | AE24: Penyerang: mengambil pergelangan tangan
A25: 4 | B25: Pertahanan dasar: kaisoku dachi, lakukan setiap teknik dengan serangan balik di ( ). | O25: 5 | P25: Chidori gaeshi kari ashi | AE25: (katate, ryote, morote), johaku,
B26: - uwa uke (tsuki), uchi uke (tsuki), shita uke (keri), soto uke (tsuki) | E26: Teknik Pilihan(100): | O26: 6 | P26: Kote maki gaeshi ~ kannuki gatame | AE26: sode atas, eri (katate)
B27: - uchi age uke (keri), uchi harai uke (keri) | E27: Lakukan kedua sisi untuk evaluasi keseluruhan. | O27: Catatan: Seorang peserta ujian menampilkan (1), (3), (5) & peserta lain | AE27: Bertahan: bertahan dan menyerang balik dengan
O28: menampilkan (2), (4), (6). Penguji menentukan siapa yang memulai terlebih dahulu. | AE28: ryuo ken, ryuka ken, rakan ken
A29: (1) Ujian teknik terdiri dari Kategori A [Teknik Dasar (100), Teknik Pilihan (100), Kumi Embu (100), dan Kategori B [Penerapan Teknik (100)]. Total Kategori A harus 70% dari 300 poin dan Kategori B harus 70% dari 300 poin untuk lulus ujian.
A30: (2) Jika Kategori A atau B kurang dari 70% dari 300 poin, hasilnya adalah Tidak Lulus. Meskipun total Kategori A mencapai skor kelulusan, jika salah satu teknik dasar, teknik pilihan atau kumi embu tidak mencapai 60% dari 100 poin, hasil ujiannya tidak lulus.
B32: Penguji 1 | E32: Penguji 2 | T32: Penguji 3
B36: Nama : | E36: Nama : | T36: Nama :
B37: DAN : | E37: DAN : | T37: DAN :
A39: 11
A40: =A39+1 -> 12
A41: =A40+1 -> 13
A42: =A41+1 -> 14
A43: =A42+1 -> 15
A44: =A43+1 -> 16
A45: =A44+1 -> 17
...

Sheet 1 DAN (Hal 2)
A1: FORMULIR - 27
A2: PENILAIAN KUMI EMBU (PAIRED EMBU) MENUJU DAN I (SATU)
A3: Tanggal :
A4: NO | B4: NAMA | C4: Ketepatan (60) | J4: Penampilan (40) | O4: Total Embu | Q4: Catatan Penguji
C5: Goho: Serangan, pertahanan, serangan balasan, 5 elemen atemi, dll. Juho: Bertahan, menghindar, melepas, menekuk pergelangan, bantingan, kuncian | I5: Sub Total | J5: 1. Komposisi, Irama dan Moderasi | K5: 2. Kuda-kuda, sikap dan keindahan | L5: 3. Kihaku (semangat), Kiai, Sae (jelas) | M5: 4. Chosoku (pernafasan), Mekubari (Perhatian), dan Zanshin | N5: Sub Total
C7: 1 | D7: 2 | E7: 3 | F7: 4 | G7: 5 | H7: 6 | J7: 1 | K7: 2 | L7: 3 | M7: 4
C8: 60 (masing-masing 10) | I8: 60 | J8: 40 (masing-masing 10) | N8: 40 | O8: 100
A9: 1 | B9: ='1 DAN'!B8 -> 0
A10: =A9+1 -> 2 | B10: ='1 DAN'!B9 -> 0 | R10: Fokus Penilaian Penguji
A11: =A10+1 -> 3 | B11: ='1 DAN'!B10 -> 0 | Q11: Ketepatan | R11: Penilaian setiap komposisi dengan titik fokus yang tercantum di bawah ini. - Goho: serangan, pertahanan, serangan balasan, 5 elemen atemi, dll. - Juho: shuho, nuki-waza, gyaku-waza, katame-waza, masing-masing prinsip, dll. Evaluasi tidak hanya kecepatan atau tampilan yang menarik, tetapi lihat apakah elemen-elemen tekniknya disusun dengan benar dan prinsip-prinsip diterapkan, untuk mengevaluasi esensi teknik tersebut. Lihat juga apakah gerakannya memiliki unsur bela diri dan masuk akal dari sudut pandang bela diri.
A12: =A11+1 -> 4 | B12: ='1 DAN'!B11 -> 0
A13: =A12+1 -> 5 | B13: ='1 DAN'!B12 -> 0
A14: =A13+1 -> 6 | B14: ='1 DAN'!B13 -> 0
A15: =A14+1 -> 7 | B15: ='1 DAN'!B14 -> 0
A16: =A15+1 -> 8 | B16: ='1 DAN'!B15 -> 0 | Q16: Penampilan | R16: 1 | S16: Komposisi, Irama, dan Moderasi | Y16: 1. Terdiri dari teknik sesuai dengan tingkatannya. 2. Tidak ada keraguan dalam melakukan rangkaian tehnik. 3. Tidak ada gerakan yang tidak perlu pada perubahan posisi dan gerakan, dll.
A17: =A16+1 -> 9 | B17: ='1 DAN'!B16 -> 0
A18: =A17+1 -> 10 | B18: ='1 DAN'!B17 -> 0
A20: Embu Berpasangan | H20: Perhatian! | R20: 2 | S20: Kuda-kuda, sikap, dan keindahan | Y20: 1. Relaks 2. Postur tubuh yang baik 3. Posisi kaki, posisi pinggul rendah, posisi kepalan tangan baik dan tangan ditekan ke samping.
A21: 1. | B21: Harai uke geri ke tsuki ten san | H21: - Seorang peserta ujian menampilkan (1), (3), (5)
B22: Bertahan : melakukan harai uke geri dan jo chu jo san ren zuki | H22: & peserta lain menampilkan (2), (4), (6)
A23: 2. | B23: Gyaku geri hiza uke nami gaeshi ke tsuki ten ichi | H23: - Penguji menentukan siapa yang memulai terlebih dahulu.
B24: Bertahan : melakukan gyaku geri hiza uke nami gaeshi dan jo chu ni ren zuki | H24: - Penguji mengevaluasi setiap peserta ujian. | R24: 3 | S24: Kihaku (semangat), Kiai, Sae (jelas) | Y24: 1.Terlihat, kihaku (bersemangat) 2. Kecepatan, kekuatan, kime, dll.
H25: - Jika peserta ujian tidak mengingat urutan embu dan penguji harus memberitahunya, setiap pemberitahuan mengurangi 2 poin dari komposisi, irama dan moderasi.
A26: 3. | B26: Morote kiri gote, Penyerang: ude ushiro neji age
A27: 4. | B27: Morote oshi nuki, Penyerang: gyaku tembin | R27: 4 | S27: Chosoku (pernafasan), Mekubari (Perhatian), dan Zanshin | Y27: 1. Ada tidak ada gangguan pernapasan. 2. Tatapan mata pada lawan. 3. Kesiapan fisik dan mental setelah teknik, dll.
A28: 5. | B28: Chidori gaeshi kari ashi
A29: 6. | B29: Kote maki gaeshi ~ kannuki gatame
B32: Penguji 1 | J32: Penguji 2 | W32: Penguji 3
B36: Nama : | J36: Nama : | W36: Nama :
B37: DAN : | J37: DAN : | W37: DAN :
A39: 11 | B39: ='1 DAN'!B39 -> 0
A40: =A39+1 -> 12 | B40: ='1 DAN'!B40 -> 0 | R40: Fokus Penilaian Penguji
A41: =A40+1 -> 13 | B41: ='1 DAN'!B41 -> 0 | Q41: Ketepatan | R41: Penilaian setiap komposisi dengan titik fokus yang tercantum di bawah ini. - Goho: serangan, pertahanan, serangan balasan, 5 elemen atemi, dll. - Juho: shuho, nuki-waza, gyaku-waza, katame-waza, masing-masing prinsip, dll. Evaluasi tidak hanya kecepatan atau tampilan yang menarik, tetapi lihat apakah elemen-elemen tekniknya disusun dengan benar dan prinsip-prinsip diterapkan, untuk mengevaluasi esensi teknik tersebut. Lihat juga apakah gerakannya memiliki unsur bela diri dan masuk akal dari sudut pandang bela diri.
A42: =A41+1 -> 14 | B42: ='1 DAN'!B42 -> 0
A43: =A42+1 -> 15 | B43: ='1 DAN'!B43 -> 0
A44: =A43+1 -> 16 | B44: ='1 DAN'!B44 -> 0
A45: =A44+1 -> 17 | B45: ='1 DAN'!B45 -> 0
A46: =A45+1 -> 18 | B46: ='1 DAN'!B46 -> 0 | Q46: Penampilan | R46: 1 | S46: Komposisi, Irama, dan Moderasi | Y46: 1. Terdiri dari teknik sesuai dengan tingkatannya. 2. Tidak ada keraguan dalam melakukan rangkaian tehnik. 3. Tidak ada gerakan yang tidak perlu pada perubahan posisi dan gerakan, dll.
A47: =A46+1 -> 19 | B47: ='1 DAN'!B47 -> 0
A48: =A47+1 -> 20 | B48: ='1 DAN'!B48 -> 0
...

Sheet F-27 Rekap
A2: Formulir - 27
A3: TABULASI PENILAIAN UJIAN
A5: Menuju : KYU - VIII
A7: No | B7: Nama | C7: NIK | D7: PengProv / PengKab / PengKot* / Pengdo | E7: Jenis Kelamin | F7: Usia (Thn) | G7: Ujian Tertulis dan/atau Lisan | I7: Ujian Praktek | J7: Jumlah Nilai | K7: Lulus (L) / Tidak Lulus (TL) | M7: Total nilai min Lulus | N7: % Hasil Ujian
G8: Teori-1 | I8: Praktek
A9: 1 | G9: 70 | I9: 210 | J9: =SUM(G9:I9) -> 280 | K9: =IF(J9>=M9,"L","TL") -> L | M9: =400*70% -> 280 | N9: =J9/400*100% -> 0.7
A10: =A9+1 -> 2 | J10: =SUM(G10:I10) -> 0 | K10: =IF(J10>=M10,"L","TL") -> TL | M10: =400*70% -> 280 | N10: =J10/400*100% -> 0
A11: =A10+1 -> 3 | J11: =SUM(G11:I11) -> 0 | K11: =IF(J11>=M11,"L","TL") -> TL | M11: =400*70% -> 280 | N11: =J11/400*100% -> 0
A12: =A11+1 -> 4 | J12: =SUM(G12:I12) -> 0 | K12: =IF(J12>=M12,"L","TL") -> TL | M12: =400*70% -> 280 | N12: =J12/400*100% -> 0
A13: =A12+1 -> 5 | J13: =SUM(G13:I13) -> 0 | K13: =IF(J13>=M13,"L","TL") -> TL | M13: =400*70% -> 280 | N13: =J13/400*100% -> 0
A14: =A13+1 -> 6 | J14: =SUM(G14:I14) -> 0 | K14: =IF(J14>=M14,"L","TL") -> TL | M14: =400*70% -> 280 | N14: =J14/400*100% -> 0
A15: =A14+1 -> 7 | J15: =SUM(G15:I15) -> 0 | K15: =IF(J15>=M15,"L","TL") -> TL | M15: =400*70% -> 280 | N15: =J15/400*100% -> 0
A16: =A15+1 -> 8 | J16: =SUM(G16:I16) -> 0 | K16: =IF(J16>=M16,"L","TL") -> TL | M16: =400*70% -> 280 | N16: =J16/400*100% -> 0
A17: =A16+1 -> 9 | J17: =SUM(G17:I17) -> 0 | K17: =IF(J17>=M17,"L","TL") -> TL | M17: =400*70% -> 280 | N17: =J17/400*100% -> 0
A18: =A17+1 -> 10 | J18: =SUM(G18:I18) -> 0 | K18: =IF(J18>=M18,"L","TL") -> TL | M18: =400*70% -> 280 | N18: =J18/400*100% -> 0
A19: =A18+1 -> 11 | J19: =SUM(G19:I19) -> 0 | K19: =IF(J19>=M19,"L","TL") -> TL | M19: =400*70% -> 280 | N19: =J19/400*100% -> 0
A20: =A19+1 -> 12 | J20: =SUM(G20:I20) -> 0 | K20: =IF(J20>=M20,"L","TL") -> TL | M20: =400*70% -> 280 | N20: =J20/400*100% -> 0
A21: =A20+1 -> 13 | J21: =SUM(G21:I21) -> 0 | K21: =IF(J21>=M21,"L","TL") -> TL | M21: =400*70% -> 280 | N21: =J21/400*100% -> 0
... A48: =A47+1 -> 40 | J48: =SUM(G48:I48) -> 0 | K48: =IF(J48>=M48,"L","TL") -> TL | M48: =400*70% -> 280 | N48: =J48/400*100% -> 0
A50: Ujian ini dilaksanakan pada : | E50: Koordinator Tim Penguji | I50: PB/Pengprov/Panpel Gashuku
A51: 1. Kegiatan : …............................................
A52: 2. Tempat : …............................................
A53: 3. Tanggal : …............................................ | E53: __________________________ | I53: _____________________________
E54: Nama : | I54: Nama :
E55: Tingkat : | I55: Tingkat :
A56: Menuju : KYU - VII
A58: No | B58: Nama | C58: NIK | D58: PengProv / PengKab / PengKot* / Pengdo | E58: Jenis Kelamin | F58: Usia (Thn) | G58: Ujian Tertulis dan/atau Lisan | I58: Ujian Praktek | J58: Jumlah Nilai | K58: Lulus (L) / Tidak Lulus (TL) | M58: Total nilai min Lulus | N58: % Hasil Ujian
G59: Teori-1 | I59: Praktek
A60: 1 | G60: 70 | I60: 210 | J60: =SUM(G60:I60) -> 280 | K60: =IF(J60>=M60,"L","TL") -> L | M60: =400*70% -> 280 | N60: =J60/400*100% -> 0.7
A61: =A60+1 -> 2 | J61: =SUM(G61:I61) -> 0 | K61: =IF(J61>=M61,"L","TL") -> TL | M61: =400*70% -> 280 | N61: =J61/400*100% -> 0
A62: =A61+1 -> 3 | J62: =SUM(G62:I62) -> 0 | K62: =IF(J62>=M62,"L","TL") -> TL | M62: =400*70% -> 280 | N62: =J62/400*100% -> 0
A63: =A62+1 -> 4 | J63: =SUM(G63:I63) -> 0 | K63: =IF(J63>=M63,"L","TL") -> TL | M63: =400*70% -> 280 | N63: =J63/400*100% -> 0
A64: =A63+1 -> 5 | J64: =SUM(G64:I64) -> 0 | K64: =IF(J64>=M64,"L","TL") -> TL | M64: =400*70% -> 280 | N64: =J64/400*100% -> 0
A65: =A64+1 -> 6 | J65: =SUM(G65:I65) -> 0 | K65: =IF(J65>=M65,"L","TL") -> TL | M65: =400*70% -> 280 | N65: =J65/400*100% -> 0
A66: =A65+1 -> 7 | J66: =SUM(G66:I66) -> 0 | K66: =IF(J66>=M66,"L","TL") -> TL | M66: =400*70% -> 280 | N66: =J66/400*100% -> 0
A67: =A66+1 -> 8 | J67: =SUM(G67:I67) -> 0 | K67: =IF(J67>=M67,"L","TL") -> TL | M67: =400*70% -> 280 | N67: =J67/400*100% -> 0
A68: =A67+1 -> 9 | J68: =SUM(G68:I68) -> 0 | K68: =IF(J68>=M68,"L","TL") -> TL | M68: =400*70% -> 280 | N68: =J68/400*100% -> 0
A69: =A68+1 -> 10 | J69: =SUM(G69:I69) -> 0 | K69: =IF(J69>=M69,"L","TL") -> TL | M69: =400*70% -> 280 | N69: =J69/400*100% -> 0
A70: =A69+1 -> 11 | J70: =SUM(G70:I70) -> 0 | K70: =IF(J70>=M70,"L","TL") -> TL | M70: =400*70% -> 280 | N70: =J70/400*100% -> 0
A71: =A70+1 -> 12 | J71: =SUM(G71:I71) -> 0 | K71: =IF(J71>=M71,"L","TL") -> TL | M71: =400*70% -> 280 | N71: =J71/400*100% -> 0
...
